Workbook

Sheet 01-quarterly-calc
A1: Filing Status: | B1: Single
A2: Prior Year AGI (2025): | B2: 78400
A3: Prior Year Total Tax (2025): | B3: 12180
A4: Safe Harbor (100% of prior year): | B4: =B3 -> 12180
A5: Quarterly Safe Harbor Payment: | B5: =B4/4 -> 3045
A8: Q1: JANUARY - MARCH
A10: 1099 Client Income | B10: 12850
A11: W-2 Gross (print shop) | B11: 5760
A12: Other Income | B12: 0
A13: Gross Income | B13: =SUM(B10:B12) -> 18610
A15: Deductions:
A16: Home office | B16: 375 | C16: simplified method, 75 sqft
A17: Business expenses | B17: 2340 | C17: new laptop, software, supplies
A18: Health insurance premium | B18: 1485
A19: Total deductions | B19: =SUM(B16:B18) -> 4200
A21: Net Self-Employment Income | B21: =B10-B19 -> 8650
A22: SE Tax (15.3% x 92.35%) | B22: =MAX(0,B21*0.153*0.9235) -> 1222.2061
A23: 1/2 SE Tax Deduction | B23: =B22/2 -> 611.10304
A25: Federal Income Tax Est. | B25: =(B21-B23+B11)*'03-tax-reference'!B5 -> 3035.7573
A26: State Income Tax Est. | B26: =(B21-B23+B11)*'03-tax-reference'!B6 -> 683.0454
A27: W-2 Withholding (already paid) | B27: 720
A29: Q1 ESTIMATED PAYMENT DUE | B29: =B22+B25+B26-B27 -> 4221.0088
A30: Due Date: 4/15/2026
A31: Paid? | B31: yes - $2,840 on 4/14
A34: Q2: APRIL - JUNE
A36: 1099 Client Income | B36: 14200 | C36: projected, update in June
A37: W-2 Gross (print shop) | B37: 5760
A38: Other Income | B38: 0
A39: Gross Income | B39: =SUM(B36:B38) -> 19960
A41: Deductions:
A42: Home office | B42: 375 | C42: simplified method, 75 sqft
A43: Business expenses | B43: 1100
A44: Health insurance premium | B44: 1485
A45: Total deductions | B45: =SUM(B42:B44) -> 2960
A47: Net Self-Employment Income | B47: =B36-B45 -> 11240
A48: SE Tax (15.3% x 92.35%) | B48: =MAX(0,B47*0.153*0.9235) -> 1588.1614
A49: 1/2 SE Tax Deduction | B49: =B48/2 -> 794.08071
A51: Federal Income Tax Est. | B51: =(B47-B49+B37)*'03-tax-reference'!B5 -> 3565.3022
A52: State Income Tax Est. | B52: =(B47-B49+B37)*'03-tax-reference'!B6 -> 802.193
A53: W-2 Withholding (already paid) | B53: 720
...

Sheet 02-income-log
A1: Date Received | B1: Client / Source | C1: Description | D1: Amount | E1: Type | F1: Quarter | G1: Notes
A2: 46032 | B2: City Print Shop | C2: Bi-weekly paycheck | D2: 960 | E2: W-2 | F2: Q1
A3: 46037 | B3: Meridian Marketing | C3: January retainer - brand strategy | D3: 3500 | E3: 1099 | F3: Q1
A4: 46046 | B4: City Print Shop | C4: Bi-weekly paycheck | D4: 960 | E4: W-2 | F4: Q1
A5: 46050 | B5: Loom & Thread Boutique | C5: Logo redesign + brand guide | D5: 1800 | E5: 1099 | F5: Q1 | G5: final payment, project started in Dec
A6: 46060 | B6: City Print Shop | C6: Bi-weekly paycheck | D6: 960 | E6: W-2 | F6: Q1
A7: 46063 | B7: BrewHaus Taproom | C7: Menu redesign + social templates | D7: 2200 | E7: 1099 | F7: Q1
A8: 46071 | B8: Meridian Marketing | C8: February retainer | D8: 3500 | E8: 1099 | F8: Q1
A9: 46074 | B9: City Print Shop | C9: Bi-weekly paycheck | D9: 1020 | E9: W-2 | F9: Q1 | G9: extra 4 hrs overtime
A10: 46086 | B10: Loom & Thread Boutique | C10: Spring campaign graphics | D10: 950 | E10: 1099 | F10: Q1
A11: 46088 | B11: City Print Shop | C11: Bi-weekly paycheck | D11: 960 | E11: W-2 | F11: Q1
A12: 46097 | B12: Meridian Marketing | C12: March retainer | D12: 3500 | E12: 1099 | F12: Q1
A13: 46102 | B13: City Print Shop | C13: Bi-weekly paycheck | D13: 960 | E13: W-2 | F13: Q1
A14: 46103 | B14: BrewHaus Taproom | C14: Event poster series (3 posters) | D14: 1400 | E14: 1099 | F14: Q1
A15: 46109 | B15: (workshop inquiry) | C15: Didn't happen | D15: 0 | E15: other | F15: Q1 | G15: fell through, rescheduled to Q3?
A16: 46116 | B16: City Print Shop | C16: Bi-weekly paycheck | D16: 960 | E16: W-2 | F16: Q2
A17: 46120 | B17: BrewHaus Taproom | C17: Tap handle label design | D17: 800 | E17: 1099 | F17: Q2
A18: 46126 | B18: Meridian Marketing | C18: April retainer | D18: 3500 | E18: 1099 | F18: Q2
A19: 46130 | B19: City Print Shop | C19: Bi-weekly paycheck | D19: 960 | E19: W-2 | F19: Q2
A22: Q1 Total (1099): | D22: =SUMPRODUCT((E2:E19="1099")*(F2:F19="Q1")*D2:D19) -> 16850
A23: Q1 Total (W-2): | D23: =SUMPRODUCT((E2:E19="W-2")*(F2:F19="Q1")*D2:D19) -> 5820
A24: Q2 Total (1099) so far: | D24: =SUMPRODUCT((E2:E19="1099")*(F2:F19="Q2")*D2:D19) -> 4300
A25: Q2 Total (W-2) so far: | D25: =SUMPRODUCT((E2:E19="W-2")*(F2:F19="Q2")*D2:D19) -> 1920
A27: ---
A28: 1099s won't arrive until Jan 2027, but I should match my totals to what clients report
A29: Meridian pays by ACH, BrewHaus pays by check (slow)

Sheet 03-tax-reference
A1: KEY RATES
A3: Filing Status: | B3: Single
A5: Federal Marginal Rate (estimated): | B5: 0.22 | C5: based on ~$55-60k taxable, 22% bracket
A6: State Rate (IL flat): | B6: 0.0495 | C6: Illinois flat rate
A7: SE Tax Rate: | B7: 0.153 | C7: 12.4% SS + 2.9% Medicare
A8: SE Taxable Factor: | B8: 0.9235 | C8: IRS says multiply net SE income by 0.9235
A10: 2026 FEDERAL TAX BRACKETS (Single)
A11: Bracket | B11: Rate | C11: Taxable Income Range
A12: 1 | B12: 10% | C12: $0 - $11,925
A13: 2 | B13: 12% | C13: $11,926 - $48,475
A14: 3 | B14: 22% | C14: $48,476 - $103,350
A15: 4 | B15: 24% | C15: $103,351 - $197,300
A16: 5 | B16: 32% | C16: $197,301 - $250,525
A17: 6 | B17: 35% | C17: $250,526 - $626,350
A18: 7 | B18: 37% | C18: Over $626,350
A20: Marcus is solidly in the 22% bracket
A22: KEY NUMBERS FOR 2026
A23: Standard Deduction (Single): | B23: 15225 | C23: updated for 2026
A24: SE Tax Threshold: | B24: 400 | C24: must file SE tax if net > $400
A25: QBI Deduction (20%): | B25: maybe? | C25: need to ask accountant, might qualify
A26: IRA Contribution Limit: | B26: 7000 | C26: haven't set this up yet
A27: HSA Limit (self-only): | B27: 4300 | C27: not eligible, on marketplace plan
A28: Estimated Tax Penalty Threshold: | B28: 1000 | C28: owe less than $1,000 = no penalty
A30: Quarterly Due Dates:
A31: Q1: April 15 | B31: Q2: June 15 | C31: Q3: September 15
A32: Q4: January 15 (next year)
A34: ---
A35: bracket numbers from IRS Rev Proc, might be slightly off
A36: ask accountant about QBI deduction for design income
A37: if I max out a SEP-IRA that would reduce taxable income a lot... look into this
