Workbook

Sheet Setup
A1: Label | B1: Value
A2: Primary Salary (monthly net) | B2: 5200
A3: Side Income | B3: 600
A4: Other Income | B4: 150
A5: Total Monthly Income | B5: =SUM(B2:B4) -> 5950
A7: Budget Categories
A8: Category | B8: Group | C8: Default Plan
A9: Rent/Mortgage | B9: Housing | C9: 1550
A10: Renters Insurance | B10: Housing | C10: 25
A11: Utilities | B11: Housing | C11: 160
A12: Internet | B12: Housing | C12: 65
A13: Car Payment | B13: Transport | C13: 380
A14: Gas | B14: Transport | C14: 140
A15: Auto Insurance | B15: Transport | C15: 110
A16: Maintenance | B16: Transport | C16: 50
A17: Parking | B17: Transport | C17: 30
A18: Groceries | B18: Food | C18: 420
A19: Dining Out | B19: Food | C19: 180
A20: Coffee | B20: Food | C20: 45
... A33: Credit Card Extra | B33: Debt | C33: 160
A35: Total Planned | C35: =SUM(C9:C33) -> 4750
A36: Remainder (should be $0) | C36: =B5-C35 -> 1200

Sheet Transactions
A1: Date | B1: Payee | C1: Amount | D1: Category | E1: Payment Method | F1: Notes
A2: 45658 | B2: Landlord LLC | C2: 1550 | D2: Rent/Mortgage | E2: Debit
A3: 45658 | B3: Lemonade | C3: 25 | D3: Renters Insurance | E3: Debit
A4: 45662 | B4: Xfinity | C4: 65 | D4: Internet | E4: Debit
A5: 45672 | B5: Honda Finance | C5: 380 | D5: Car Payment | E5: Debit
A6: 45658 | B6: Geico | C6: 110 | D6: Auto Insurance | E6: Debit
A7: 45658 | B7: Blue Cross | C7: 210 | D7: Health Insurance | E7: Debit
A8: 45658 | B8: Planet Fitness | C8: 45 | D8: Gym | E8: Debit
A9: 45685 | B9: Navient | C9: 280 | D9: Student Loan | E9: Debit
A10: 45677 | B10: Chase Visa Extra | C10: 160 | D10: Credit Card Extra | E10: Transfer
A11: 45672 | B11: Transfer to Savings | C11: 300 | D11: Emergency Fund | E11: Transfer
A12: 45672 | B12: Vanguard Transfer | C12: 200 | D12: Retirement Extra | E12: Transfer
A13: 45672 | B13: Transfer to Vacation | C13: 100 | D13: Vacation Fund | E13: Transfer
... A280: 45998 | B280: Discount Tire | C280: 142.27 | D280: Maintenance | E280: Debit

Sheet Monthly Plan
A1: Category | B1: Group | C1: Jan | D1: Feb | E1: Mar | F1: Apr | G1: May | H1: Jun | I1: Jul | J1: Aug | K1: Sep | L1: Oct | M1: Nov | N1: Dec | O1: Annual
A2: Monthly Income | C2: =Setup!$B$5 -> 5950 | D2: =Setup!$B$5 -> 5950 | E2: =Setup!$B$5 -> 5950 | F2: =Setup!$B$5 -> 5950 | G2: =Setup!$B$5 -> 5950 | H2: =Setup!$B$5 -> 5950 | I2: =Setup!$B$5 -> 5950 | J2: =Setup!$B$5 -> 5950 | ... N2: =Setup!$B$5 -> 5950 | O2: =SUM(C2:N2) -> 71400
A3: Rent/Mortgage | B3: Housing | C3: =Setup!$C$9 -> 1550 | D3: =Setup!$C$9 -> 1550 | E3: =Setup!$C$9 -> 1550 | F3: =Setup!$C$9 -> 1550 | G3: =Setup!$C$9 -> 1550 | H3: =Setup!$C$9 -> 1550 | I3: =Setup!$C$9 -> 1550 | J3: =Setup!$C$9 -> 1550 | ... N3: =Setup!$C$9 -> 1550 | O3: =SUM(C3:N3) -> 18600
A4: Renters Insurance | B4: Housing | C4: =Setup!$C$10 -> 25 | D4: =Setup!$C$10 -> 25 | E4: =Setup!$C$10 -> 25 | F4: =Setup!$C$10 -> 25 | G4: =Setup!$C$10 -> 25 | H4: =Setup!$C$10 -> 25 | I4: =Setup!$C$10 -> 25 | J4: =Setup!$C$10 -> 25 | ... N4: =Setup!$C$10 -> 25 | O4: =SUM(C4:N4) -> 300
A5: Utilities | B5: Housing | C5: =Setup!$C$11 -> 160 | D5: =Setup!$C$11 -> 160 | E5: =Setup!$C$11 -> 160 | F5: =Setup!$C$11 -> 160 | G5: =Setup!$C$11 -> 160 | H5: =Setup!$C$11 -> 160 | I5: =Setup!$C$11 -> 160 | J5: =Setup!$C$11 -> 160 | ... N5: =Setup!$C$11 -> 160 | O5: =SUM(C5:N5) -> 1920
A6: Internet | B6: Housing | C6: =Setup!$C$12 -> 65 | D6: =Setup!$C$12 -> 65 | E6: =Setup!$C$12 -> 65 | F6: =Setup!$C$12 -> 65 | G6: =Setup!$C$12 -> 65 | H6: =Setup!$C$12 -> 65 | I6: =Setup!$C$12 -> 65 | J6: =Setup!$C$12 -> 65 | ... N6: =Setup!$C$12 -> 65 | O6: =SUM(C6:N6) -> 780
A7: Car Payment | B7: Transport | C7: =Setup!$C$13 -> 380 | D7: =Setup!$C$13 -> 380 | E7: =Setup!$C$13 -> 380 | F7: =Setup!$C$13 -> 380 | G7: =Setup!$C$13 -> 380 | H7: =Setup!$C$13 -> 380 | I7: =Setup!$C$13 -> 380 | J7: =Setup!$C$13 -> 380 | ... N7: =Setup!$C$13 -> 380 | O7: =SUM(C7:N7) -> 4560
A8: Gas | B8: Transport | C8: =Setup!$C$14 -> 140 | D8: =Setup!$C$14 -> 140 | E8: =Setup!$C$14 -> 140 | F8: =Setup!$C$14 -> 140 | G8: =Setup!$C$14 -> 140 | H8: =Setup!$C$14 -> 140 | I8: =Setup!$C$14 -> 140 | J8: =Setup!$C$14 -> 140 | ... N8: =Setup!$C$14 -> 140 | O8: =SUM(C8:N8) -> 1680
A9: Auto Insurance | B9: Transport | C9: =Setup!$C$15 -> 110 | D9: =Setup!$C$15 -> 110 | E9: =Setup!$C$15 -> 110 | F9: =Setup!$C$15 -> 110 | G9: =Setup!$C$15 -> 110 | H9: =Setup!$C$15 -> 110 | I9: =Setup!$C$15 -> 110 | J9: =Setup!$C$15 -> 110 | ... N9: =Setup!$C$15 -> 110 | O9: =SUM(C9:N9) -> 1320
A10: Maintenance | B10: Transport | C10: =Setup!$C$16 -> 50 | D10: =Setup!$C$16 -> 50 | E10: =Setup!$C$16 -> 50 | F10: =Setup!$C$16 -> 50 | G10: =Setup!$C$16 -> 50 | H10: =Setup!$C$16 -> 50 | I10: =Setup!$C$16 -> 50 | J10: =Setup!$C$16 -> 50 | ... N10: =Setup!$C$16 -> 50 | O10: =SUM(C10:N10) -> 600
A11: Parking | B11: Transport | C11: =Setup!$C$17 -> 30 | D11: =Setup!$C$17 -> 30 | E11: =Setup!$C$17 -> 30 | F11: =Setup!$C$17 -> 30 | G11: =Setup!$C$17 -> 30 | H11: =Setup!$C$17 -> 30 | I11: =Setup!$C$17 -> 30 | J11: =Setup!$C$17 -> 30 | ... N11: =Setup!$C$17 -> 30 | O11: =SUM(C11:N11) -> 360
A12: Groceries | B12: Food | C12: =Setup!$C$18 -> 420 | D12: =Setup!$C$18 -> 420 | E12: =Setup!$C$18 -> 420 | F12: =Setup!$C$18 -> 420 | G12: =Setup!$C$18 -> 420 | H12: =Setup!$C$18 -> 420 | I12: =Setup!$C$18 -> 420 | J12: =Setup!$C$18 -> 420 | ... N12: =Setup!$C$18 -> 420 | O12: =SUM(C12:N12) -> 5040
A13: Dining Out | B13: Food | C13: =Setup!$C$19 -> 180 | D13: =Setup!$C$19 -> 180 | E13: =Setup!$C$19 -> 180 | F13: =Setup!$C$19 -> 180 | G13: =Setup!$C$19 -> 180 | H13: =Setup!$C$19 -> 180 | I13: =Setup!$C$19 -> 180 | J13: =Setup!$C$19 -> 180 | ... N13: =Setup!$C$19 -> 180 | O13: =SUM(C13:N13) -> 2160
A14: Coffee | B14: Food | C14: =Setup!$C$20 -> 45 | D14: =Setup!$C$20 -> 45 | E14: =Setup!$C$20 -> 45 | F14: =Setup!$C$20 -> 45 | G14: =Setup!$C$20 -> 45 | H14: =Setup!$C$20 -> 45 | I14: =Setup!$C$20 -> 45 | J14: =Setup!$C$20 -> 45 | ... N14: =Setup!$C$20 -> 45 | O14: =SUM(C14:N14) -> 540
A15: Clothing | B15: Personal | C15: =Setup!$C$21 -> 75 | D15: =Setup!$C$21 -> 75 | E15: =Setup!$C$21 -> 75 | F15: =Setup!$C$21 -> 75 | G15: =Setup!$C$21 -> 75 | H15: =Setup!$C$21 -> 75 | I15: =Setup!$C$21 -> 75 | J15: =Setup!$C$21 -> 75 | ... N15: =Setup!$C$21 -> 75 | O15: =SUM(C15:N15) -> 900
A16: Haircuts | B16: Personal | C16: =Setup!$C$22 -> 30 | D16: =Setup!$C$22 -> 30 | E16: =Setup!$C$22 -> 30 | F16: =Setup!$C$22 -> 30 | G16: =Setup!$C$22 -> 30 | H16: =Setup!$C$22 -> 30 | I16: =Setup!$C$22 -> 30 | J16: =Setup!$C$22 -> 30 | ... N16: =Setup!$C$22 -> 30 | O16: =SUM(C16:N16) -> 360
A17: Subscriptions | B17: Personal | C17: =Setup!$C$23 -> 55 | D17: =Setup!$C$23 -> 55 | E17: =Setup!$C$23 -> 55 | F17: =Setup!$C$23 -> 55 | G17: =Setup!$C$23 -> 55 | H17: =Setup!$C$23 -> 55 | I17: =Setup!$C$23 -> 55 | J17: =Setup!$C$23 -> 55 | ... N17: =Setup!$C$23 -> 55 | O17: =SUM(C17:N17) -> 660
A18: Entertainment | B18: Personal | C18: =Setup!$C$24 -> 80 | D18: =Setup!$C$24 -> 80 | E18: =Setup!$C$24 -> 80 | F18: =Setup!$C$24 -> 80 | G18: =Setup!$C$24 -> 80 | H18: =Setup!$C$24 -> 80 | I18: =Setup!$C$24 -> 80 | J18: =Setup!$C$24 -> 80 | ... N18: =Setup!$C$24 -> 80 | O18: =SUM(C18:N18) -> 960
A19: Gifts | B19: Personal | C19: =Setup!$C$25 -> 40 | D19: =Setup!$C$25 -> 40 | E19: =Setup!$C$25 -> 40 | F19: =Setup!$C$25 -> 40 | G19: =Setup!$C$25 -> 40 | H19: =Setup!$C$25 -> 40 | I19: =Setup!$C$25 -> 40 | J19: =Setup!$C$25 -> 40 | ... N19: =Setup!$C$25 -> 40 | O19: =SUM(C19:N19) -> 480
A20: Health Insurance | B20: Health | C20: =Setup!$C$26 -> 210 | D20: =Setup!$C$26 -> 210 | E20: =Setup!$C$26 -> 210 | F20: =Setup!$C$26 -> 210 | G20: =Setup!$C$26 -> 210 | H20: =Setup!$C$26 -> 210 | I20: =Setup!$C$26 -> 210 | J20: =Setup!$C$26 -> 210 | ... N20: =Setup!$C$26 -> 210 | O20: =SUM(C20:N20) -> 2520
A21: Gym | B21: Health | C21: =Setup!$C$27 -> 45 | D21: =Setup!$C$27 -> 45 | E21: =Setup!$C$27 -> 45 | F21: =Setup!$C$27 -> 45 | G21: =Setup!$C$27 -> 45 | H21: =Setup!$C$27 -> 45 | I21: =Setup!$C$27 -> 45 | J21: =Setup!$C$27 -> 45 | ... N21: =Setup!$C$27 -> 45 | O21: =SUM(C21:N21) -> 540
A22: Prescriptions | B22: Health | C22: =Setup!$C$28 -> 20 | D22: =Setup!$C$28 -> 20 | E22: =Setup!$C$28 -> 20 | F22: =Setup!$C$28 -> 20 | G22: =Setup!$C$28 -> 20 | H22: =Setup!$C$28 -> 20 | I22: =Setup!$C$28 -> 20 | J22: =Setup!$C$28 -> 20 | ... N22: =Setup!$C$28 -> 20 | O22: =SUM(C22:N22) -> 240
A23: Emergency Fund | B23: Savings | C23: =Setup!$C$29 -> 300 | D23: =Setup!$C$29 -> 300 | E23: =Setup!$C$29 -> 300 | F23: =Setup!$C$29 -> 300 | G23: =Setup!$C$29 -> 300 | H23: =Setup!$C$29 -> 300 | I23: =Setup!$C$29 -> 300 | J23: =Setup!$C$29 -> 300 | ... N23: =Setup!$C$29 -> 300 | O23: =SUM(C23:N23) -> 3600
A24: Retirement Extra | B24: Savings | C24: =Setup!$C$30 -> 200 | D24: =Setup!$C$30 -> 200 | E24: =Setup!$C$30 -> 200 | F24: =Setup!$C$30 -> 200 | G24: =Setup!$C$30 -> 200 | H24: =Setup!$C$30 -> 200 | I24: =Setup!$C$30 -> 200 | J24: =Setup!$C$30 -> 200 | ... N24: =Setup!$C$30 -> 200 | O24: =SUM(C24:N24) -> 2400
A25: Vacation Fund | B25: Savings | C25: =Setup!$C$31 -> 100 | D25: =Setup!$C$31 -> 100 | E25: =Setup!$C$31 -> 100 | F25: =Setup!$C$31 -> 100 | G25: =Setup!$C$31 -> 100 | H25: =Setup!$C$31 -> 100 | I25: =Setup!$C$31 -> 100 | J25: =Setup!$C$31 -> 100 | ... N25: =Setup!$C$31 -> 100 | O25: =SUM(C25:N25) -> 1200
A26: Student Loan | B26: Debt | C26: =Setup!$C$32 -> 280 | D26: =Setup!$C$32 -> 280 | E26: =Setup!$C$32 -> 280 | F26: =Setup!$C$32 -> 280 | G26: =Setup!$C$32 -> 280 | H26: =Setup!$C$32 -> 280 | I26: =Setup!$C$32 -> 280 | J26: =Setup!$C$32 -> 280 | ... N26: =Setup!$C$32 -> 280 | O26: =SUM(C26:N26) -> 3360
A27: Credit Card Extra | B27: Debt | C27: =Setup!$C$33 -> 160 | D27: =Setup!$C$33 -> 160 | E27: =Setup!$C$33 -> 160 | F27: =Setup!$C$33 -> 160 | G27: =Setup!$C$33 -> 160 | H27: =Setup!$C$33 -> 160 | I27: =Setup!$C$33 -> 160 | J27: =Setup!$C$33 -> 160 | ... N27: =Setup!$C$33 -> 160 | O27: =SUM(C27:N27) -> 1920
A28: Total Planned | C28: =SUM(C3:C27) -> 4750 | D28: =SUM(D3:D27) -> 4750 | E28: =SUM(E3:E27) -> 4750 | F28: =SUM(F3:F27) -> 4750 | G28: =SUM(G3:G27) -> 4750 | H28: =SUM(H3:H27) -> 4750 | I28: =SUM(I3:I27) -> 4750 | J28: =SUM(J3:J27) -> 4750 | ... N28: =SUM(N3:N27) -> 4750 | O28: =SUM(C28:N28) -> 57000
A29: Remainder | C29: =C2-C28 -> 1200 | D29: =D2-D28 -> 1200 | E29: =E2-E28 -> 1200 | F29: =F2-F28 -> 1200 | G29: =G2-G28 -> 1200 | H29: =H2-H28 -> 1200 | I29: =I2-I28 -> 1200 | J29: =J2-J28 -> 1200 | ... N29: =N2-N28 -> 1200

Sheet Actuals vs Plan
A1: Category | B1: Jan Plan | C1: Jan Actual | D1: Jan Var | E1: Feb Plan | F1: Feb Actual | G1: Feb Var | H1: Mar Plan | I1: Mar Actual | J1: Mar Var | K1: Apr Plan | L1: Apr Actual | M1: Apr Var | N1: May Plan | O1: May Actual | P1: May Var | Q1: Jun Plan | R1: Jun Actual | S1: Jun Var | T1: Jul Plan | U1: Jul Actual | V1: Jul Var | W1: Aug Plan | X1: Aug Actual | Y1: Aug Var | Z1: Sep Plan | AA1: Sep Actual | AB1: Sep Var | AC1: Oct Plan | AD1: Oct Actual | AE1: Oct Var | AF1: Nov Plan | AG1: Nov Actual | AH1: Nov Var | AI1: Dec Plan | AJ1: Dec Actual | AK1: Dec Var | AL1: Annual Plan | AM1: Annual Actual | AN1: Annual Var
A2: Rent/Mortgage | B2: ='Monthly Plan'!C3 -> 1550 | C2: =SUMPRODUCT((MONTH(Transactions!$A$2:$A$280)=1)*(Transactions!$D$2:$D$280="Rent/Mortgage")*Transactions!$C$2:$C$280) -> 1550 | D2: =B2-C2 -> 0 | E2: ='Monthly Plan'!D3 -> 1550 | F2: =SUMPRODUCT((MONTH(Transactions!$A$2:$A$280)=2)*(Transactions!$D$2:$D$280="Rent/Mortgage")*Transactions!$C$2:$C$280) -> 1550 | G2: =E2-F2 -> 0 | H2: ='Monthly Plan'!E3 -> 1550 | I2: =SUMPRODUCT((MONTH(Transactions!$A$2:$A$280)=3)*(Transactions!$D$2:$D$280="Rent/Mortgage")*Transactions!$C$2:$C$280) -> 1550 | J2: =H2-I2 -> 0 | K2: ='Monthly Plan'!F3 -> 1550 | L2: =SUMPRODUCT((MONTH(Transactions!$A$2:$A$280)=4)*(Transactions!$D$2:$D$280="Rent/Mortgage")*Transactions!$C$2:$C$280) -> 1550 | M2: =K2-L2 -> 0 | N2: ='Monthly Plan'!G3 -> 1550 | O2: =SUMPRODUCT((MONTH(Transactions!$A$2:$A$280)=5)*(Transactions!$D$2:$D$280="Rent/Mortgage")*Transactions!$C$2:$C$280) -> 1550 | P2: =N2-O2 -> 0 | Q2: ='Monthly Plan'!H3 -> 1550 | R2: =SUMPRODUCT((MONTH(Transactions!$A$2:$A$280)=6)*(Transactions!$D$2:$D$280="Rent/Mortgage")*Transactions!$C$2:$C$280) -> 1550 | S2: =Q2-R2 -> 0 | T2: ='Monthly Plan'!I3 -> 1550 | U2: =SUMPRODUCT((MONTH(Transactions!$A$2:$A$280)=7)*(Transactions!$D$2:$D$280="Rent/Mortgage")*Transactions!$C$2:$C$280) -> 1550 | V2: =T2-U2 -> 0 | W2: ='Monthly Plan'!J3 -> 1550 | X2: =SUMPRODUCT((MONTH(Transactions!$A$2:$A$280)=8)*(Transactions!$D$2:$D$280="Rent/Mortgage")*Transactions!$C$2:$C$280) -> 1550 | Y2: =W2-X2 -> 0 | Z2: ='Monthly Plan'!K3 -> 1550 | AA2: =SUMPRODUCT((MONTH(Transactions!$A$2:$A$280)=9)*(Transactions!$D$2:$D$280="Rent/Mortgage")*Transactions!$C$2:$C$280) -> 1550 | AB2: =Z2-AA2 -> 0 | AC2: ='Monthly Plan'!L3 -> 1550 | AD2: =SUMPRODUCT((MONTH(Transactions!$A$2:$A$280)=10)*(Transactions!$D$2:$D$280="Rent/Mortgage")*Transactions!$C$2:$C$280) -> 1550 | AE2: =AC2-AD2 -> 0 | AF2: ='Monthly Plan'!M3 -> 1550 | AG2: =SUMPRODUCT((MONTH(Transactions!$A$2:$A$280)=11)*(Transactions!$D$2:$D$280="Rent/Mortgage")*Transactions!$C$2:$C$280) -> 1550 | AH2: =AF2-AG2 -> 0 | AI2: ='Monthly Plan'!N3 -> 1550 | AJ2: =SUMPRODUCT((MONTH(Transactions!$A$2:$A$280)=12)*(Transactions!$D$2:$D$280="Rent/Mortgage")*Transactions!$C$2:$C$280) -> 1550 | AK2: =AI2-AJ2 -> 0 | AL2: =B2+E2+H2+K2+N2+Q2+T2+W2+Z2+AC2+AF2+AI2 -> 18600 | AM2: =C2+F2+I2+L2+O2+R2+U2+X2+AA2+AD2+AG2+AJ2 -> 18600 | AN2: =AL2-AM2 -> 0
A3: Renters Insurance | B3: ='Monthly Plan'!C4 -> 25 | C3: =SUMPRODUCT((MONTH(Transactions!$A$2:$A$280)=1)*(Transactions!$D$2:$D$280="Renters Insurance")*Transactions!$C$2:$C$280) -> 25 | D3: =B3-C3 -> 0 | E3: ='Monthly Plan'!D4 -> 25 | F3: =SUMPRODUCT((MONTH(Transactions!$A$2:$A$280)=2)*(Transactions!$D$2:$D$280="Renters Insurance")*Transactions!$C$2:$C$280) -> 25 | G3: =E3-F3 -> 0 | H3: ='Monthly Plan'!E4 -> 25 | I3: =SUMPRODUCT((MONTH(Transactions!$A$2:$A$280)=3)*(Transactions!$D$2:$D$280="Renters Insurance")*Transactions!$C$2:$C$280) -> 25 | J3: =H3-I3 -> 0 | K3: ='Monthly Plan'!F4 -> 25 | L3: =SUMPRODUCT((MONTH(Transactions!$A$2:$A$280)=4)*(Transactions!$D$2:$D$280="Renters Insurance")*Transactions!$C$2:$C$280) -> 25 | M3: =K3-L3 -> 0 | N3: ='Monthly Plan'!G4 -> 25 | O3: =SUMPRODUCT((MONTH(Transactions!$A$2:$A$280)=5)*(Transactions!$D$2:$D$280="Renters Insurance")*Transactions!$C$2:$C$280) -> 25 | P3: =N3-O3 -> 0 | Q3: ='Monthly Plan'!H4 -> 25 | R3: =SUMPRODUCT((MONTH(Transactions!$A$2:$A$280)=6)*(Transactions!$D$2:$D$280="Renters Insurance")*Transactions!$C$2:$C$280) -> 25 | S3: =Q3-R3 -> 0 | T3: ='Monthly Plan'!I4 -> 25 | U3: =SUMPRODUCT((MONTH(Transactions!$A$2:$A$280)=7)*(Transactions!$D$2:$D$280="Renters Insurance")*Transactions!$C$2:$C$280) -> 25 | V3: =T3-U3 -> 0 | W3: ='Monthly Plan'!J4 -> 25 | X3: =SUMPRODUCT((MONTH(Transactions!$A$2:$A$280)=8)*(Transactions!$D$2:$D$280="Renters Insurance")*Transactions!$C$2:$C$280) -> 25 | Y3: =W3-X3 -> 0 | Z3: ='Monthly Plan'!K4 -> 25 | AA3: =SUMPRODUCT((MONTH(Transactions!$A$2:$A$280)=9)*(Transactions!$D$2:$D$280="Renters Insurance")*Transactions!$C$2:$C$280) -> 25 | AB3: =Z3-AA3 -> 0 | AC3: ='Monthly Plan'!L4 -> 25 | AD3: =SUMPRODUCT((MONTH(Transactions!$A$2:$A$280)=10)*(Transactions!$D$2:$D$280="Renters Insurance")*Transactions!$C$2:$C$280) -> 25 | AE3: =AC3-AD3 -> 0 | AF3: ='Monthly Plan'!M4 -> 25 | AG3: =SUMPRODUCT((MONTH(Transactions!$A$2:$A$280)=11)*(Transactions!$D$2:$D$280="Renters Insurance")*Transactions!$C$2:$C$280) -> 25 | AH3: =AF3-AG3 -> 0 | AI3: ='Monthly Plan'!N4 -> 25 | AJ3: =SUMPRODUCT((MONTH(Transactions!$A$2:$A$280)=12)*(Transactions!$D$2:$D$280="Renters Insurance")*Transactions!$C$2:$C$280) -> 25 | AK3: =AI3-AJ3 -> 0 | AL3: =B3+E3+H3+K3+N3+Q3+T3+W3+Z3+AC3+AF3+AI3 -> 300 | AM3: =C3+F3+I3+L3+O3+R3+U3+X3+AA3+AD3+AG3+AJ3 -> 300 | AN3: =AL3-AM3 -> 0
A4: Utilities | B4: ='Monthly Plan'!C5 -> 160 | C4: =SUMPRODUCT((MONTH(Transactions!$A$2:$A$280)=1)*(Transactions!$D$2:$D$280="Utilities")*Transactions!$C$2:$C$280) -> 185.53 | D4: =B4-C4 -> -25.53 | E4: ='Monthly Plan'!D5 -> 160 | F4: =SUMPRODUCT((MONTH(Transactions!$A$2:$A$280)=2)*(Transactions!$D$2:$D$280="Utilities")*Transactions!$C$2:$C$280) -> 152.76 | G4: =E4-F4 -> 7.24 | H4: ='Monthly Plan'!E5 -> 160 | I4: =SUMPRODUCT((MONTH(Transactions!$A$2:$A$280)=3)*(Transactions!$D$2:$D$280="Utilities")*Transactions!$C$2:$C$280) -> 198.68 | J4: =H4-I4 -> -38.68 | K4: ='Monthly Plan'!F5 -> 160 | L4: =SUMPRODUCT((MONTH(Transactions!$A$2:$A$280)=4)*(Transactions!$D$2:$D$280="Utilities")*Transactions!$C$2:$C$280) -> 166.59 | M4: =K4-L4 -> -6.59 | N4: ='Monthly Plan'!G5 -> 160 | O4: =SUMPRODUCT((MONTH(Transactions!$A$2:$A$280)=5)*(Transactions!$D$2:$D$280="Utilities")*Transactions!$C$2:$C$280) -> 195.74 | P4: =N4-O4 -> -35.74 | Q4: ='Monthly Plan'!H5 -> 160 | R4: =SUMPRODUCT((MONTH(Transactions!$A$2:$A$280)=6)*(Transactions!$D$2:$D$280="Utilities")*Transactions!$C$2:$C$280) -> 161.88 | S4: =Q4-R4 -> -1.88 | T4: ='Monthly Plan'!I5 -> 160 | U4: =SUMPRODUCT((MONTH(Transactions!$A$2:$A$280)=7)*(Transactions!$D$2:$D$280="Utilities")*Transactions!$C$2:$C$280) -> 140.1 | V4: =T4-U4 -> 19.9 | W4: ='Monthly Plan'!J5 -> 160 | X4: =SUMPRODUCT((MONTH(Transactions!$A$2:$A$280)=8)*(Transactions!$D$2:$D$280="Utilities")*Transactions!$C$2:$C$280) -> 188.25 | Y4: =W4-X4 -> -28.25 | Z4: ='Monthly Plan'!K5 -> 160 | AA4: =SUMPRODUCT((MONTH(Transactions!$A$2:$A$280)=9)*(Transactions!$D$2:$D$280="Utilities")*Transactions!$C$2:$C$280) -> 169.29 | AB4: =Z4-AA4 -> -9.29 | AC4: ='Monthly Plan'!L5 -> 160 | AD4: =SUMPRODUCT((MONTH(Transactions!$A$2:$A$280)=10)*(Transactions!$D$2:$D$280="Utilities")*Transactions!$C$2:$C$280) -> 195.73 | AE4: =AC4-AD4 -> -35.73 | AF4: ='Monthly Plan'!M5 -> 160 | AG4: =SUMPRODUCT((MONTH(Transactions!$A$2:$A$280)=11)*(Transactions!$D$2:$D$280="Utilities")*Transactions!$C$2:$C$280) -> 173.35 | AH4: =AF4-AG4 -> -13.35 | AI4: ='Monthly Plan'!N5 -> 160 | AJ4: =SUMPRODUCT((MONTH(Transactions!$A$2:$A$280)=12)*(Transactions!$D$2:$D$280="Utilities")*Transactions!$C$2:$C$280) -> 146.16 | AK4: =AI4-AJ4 -> 13.84 | AL4: =B4+E4+H4+K4+N4+Q4+T4+W4+Z4+AC4+AF4+AI4 -> 1920 | AM4: =C4+F4+I4+L4+O4+R4+U4+X4+AA4+AD4+AG4+AJ4 -> 2074.06 | AN4: =AL4-AM4 -> -154.06
A5: Internet | B5: ='Monthly Plan'!C6 -> 65 | C5: =SUMPRODUCT((MONTH(Transactions!$A$2:$A$280)=1)*(Transactions!$D$2:$D$280="Internet")*Transactions!$C$2:$C$280) -> 65 | D5: =B5-C5 -> 0 | E5: ='Monthly Plan'!D6 -> 65 | F5: =SUMPRODUCT((MONTH(Transactions!$A$2:$A$280)=2)*(Transactions!$D$2:$D$280="Internet")*Transactions!$C$2:$C$280) -> 65 | G5: =E5-F5 -> 0 | H5: ='Monthly Plan'!E6 -> 65 | I5: =SUMPRODUCT((MONTH(Transactions!$A$2:$A$280)=3)*(Transactions!$D$2:$D$280="Internet")*Transactions!$C$2:$C$280) -> 65 | J5: =H5-I5 -> 0 | K5: ='Monthly Plan'!F6 -> 65 | L5: =SUMPRODUCT((MONTH(Transactions!$A$2:$A$280)=4)*(Transactions!$D$2:$D$280="Internet")*Transactions!$C$2:$C$280) -> 65 | M5: =K5-L5 -> 0 | N5: ='Monthly Plan'!G6 -> 65 | O5: =SUMPRODUCT((MONTH(Transactions!$A$2:$A$280)=5)*(Transactions!$D$2:$D$280="Internet")*Transactions!$C$2:$C$280) -> 65 | P5: =N5-O5 -> 0 | Q5: ='Monthly Plan'!H6 -> 65 | R5: =SUMPRODUCT((MONTH(Transactions!$A$2:$A$280)=6)*(Transactions!$D$2:$D$280="Internet")*Transactions!$C$2:$C$280) -> 65 | S5: =Q5-R5 -> 0 | T5: ='Monthly Plan'!I6 -> 65 | U5: =SUMPRODUCT((MONTH(Transactions!$A$2:$A$280)=7)*(Transactions!$D$2:$D$280="Internet")*Transactions!$C$2:$C$280) -> 65 | V5: =T5-U5 -> 0 | W5: ='Monthly Plan'!J6 -> 65 | X5: =SUMPRODUCT((MONTH(Transactions!$A$2:$A$280)=8)*(Transactions!$D$2:$D$280="Internet")*Transactions!$C$2:$C$280) -> 65 | Y5: =W5-X5 -> 0 | Z5: ='Monthly Plan'!K6 -> 65 | AA5: =SUMPRODUCT((MONTH(Transactions!$A$2:$A$280)=9)*(Transactions!$D$2:$D$280="Internet")*Transactions!$C$2:$C$280) -> 65 | AB5: =Z5-AA5 -> 0 | AC5: ='Monthly Plan'!L6 -> 65 | AD5: =SUMPRODUCT((MONTH(Transactions!$A$2:$A$280)=10)*(Transactions!$D$2:$D$280="Internet")*Transactions!$C$2:$C$280) -> 65 | AE5: =AC5-AD5 -> 0 | AF5: ='Monthly Plan'!M6 -> 65 | AG5: =SUMPRODUCT((MONTH(Transactions!$A$2:$A$280)=11)*(Transactions!$D$2:$D$280="Internet")*Transactions!$C$2:$C$280) -> 65 | AH5: =AF5-AG5 -> 0 | AI5: ='Monthly Plan'!N6 -> 65 | AJ5: =SUMPRODUCT((MONTH(Transactions!$A$2:$A$280)=12)*(Transactions!$D$2:$D$280="Internet")*Transactions!$C$2:$C$280) -> 65 | AK5: =AI5-AJ5 -> 0 | AL5: =B5+E5+H5+K5+N5+Q5+T5+W5+Z5+AC5+AF5+AI5 -> 780 | AM5: =C5+F5+I5+L5+O5+R5+U5+X5+AA5+AD5+AG5+AJ5 -> 780 | AN5: =AL5-AM5 -> 0
A6: Car Payment | B6: ='Monthly Plan'!C7 -> 380 | C6: =SUMPRODUCT((MONTH(Transactions!$A$2:$A$280)=1)*(Transactions!$D$2:$D$280="Car Payment")*Transactions!$C$2:$C$280) -> 380 | D6: =B6-C6 -> 0 | E6: ='Monthly Plan'!D7 -> 380 | F6: =SUMPRODUCT((MONTH(Transactions!$A$2:$A$280)=2)*(Transactions!$D$2:$D$280="Car Payment")*Transactions!$C$2:$C$280) -> 380 | G6: =E6-F6 -> 0 | H6: ='Monthly Plan'!E7 -> 380 | I6: =SUMPRODUCT((MONTH(Transactions!$A$2:$A$280)=3)*(Transactions!$D$2:$D$280="Car Payment")*Transactions!$C$2:$C$280) -> 380 | J6: =H6-I6 -> 0 | K6: ='Monthly Plan'!F7 -> 380 | L6: =SUMPRODUCT((MONTH(Transactions!$A$2:$A$280)=4)*(Transactions!$D$2:$D$280="Car Payment")*Transactions!$C$2:$C$280) -> 380 | M6: =K6-L6 -> 0 | N6: ='Monthly Plan'!G7 -> 380 | O6: =SUMPRODUCT((MONTH(Transactions!$A$2:$A$280)=5)*(Transactions!$D$2:$D$280="Car Payment")*Transactions!$C$2:$C$280) -> 380 | P6: =N6-O6 -> 0 | Q6: ='Monthly Plan'!H7 -> 380 | R6: =SUMPRODUCT((MONTH(Transactions!$A$2:$A$280)=6)*(Transactions!$D$2:$D$280="Car Payment")*Transactions!$C$2:$C$280) -> 380 | S6: =Q6-R6 -> 0 | T6: ='Monthly Plan'!I7 -> 380 | U6: =SUMPRODUCT((MONTH(Transactions!$A$2:$A$280)=7)*(Transactions!$D$2:$D$280="Car Payment")*Transactions!$C$2:$C$280) -> 380 | V6: =T6-U6 -> 0 | W6: ='Monthly Plan'!J7 -> 380 | X6: =SUMPRODUCT((MONTH(Transactions!$A$2:$A$280)=8)*(Transactions!$D$2:$D$280="Car Payment")*Transactions!$C$2:$C$280) -> 380 | Y6: =W6-X6 -> 0 | Z6: ='Monthly Plan'!K7 -> 380 | AA6: =SUMPRODUCT((MONTH(Transactions!$A$2:$A$280)=9)*(Transactions!$D$2:$D$280="Car Payment")*Transactions!$C$2:$C$280) -> 380 | AB6: =Z6-AA6 -> 0 | AC6: ='Monthly Plan'!L7 -> 380 | AD6: =SUMPRODUCT((MONTH(Transactions!$A$2:$A$280)=10)*(Transactions!$D$2:$D$280="Car Payment")*Transactions!$C$2:$C$280) -> 380 | AE6: =AC6-AD6 -> 0 | AF6: ='Monthly Plan'!M7 -> 380 | AG6: =SUMPRODUCT((MONTH(Transactions!$A$2:$A$280)=11)*(Transactions!$D$2:$D$280="Car Payment")*Transactions!$C$2:$C$280) -> 380 | AH6: =AF6-AG6 -> 0 | AI6: ='Monthly Plan'!N7 -> 380 | AJ6: =SUMPRODUCT((MONTH(Transactions!$A$2:$A$280)=12)*(Transactions!$D$2:$D$280="Car Payment")*Transactions!$C$2:$C$280) -> 380 | AK6: =AI6-AJ6 -> 0 | AL6: =B6+E6+H6+K6+N6+Q6+T6+W6+Z6+AC6+AF6+AI6 -> 4560 | AM6: =C6+F6+I6+L6+O6+R6+U6+X6+AA6+AD6+AG6+AJ6 -> 4560 | AN6: =AL6-AM6 -> 0
A7: Gas | B7: ='Monthly Plan'!C8 -> 140 | C7: =SUMPRODUCT((MONTH(Transactions!$A$2:$A$280)=1)*(Transactions!$D$2:$D$280="Gas")*Transactions!$C$2:$C$280) -> 127.22 | D7: =B7-C7 -> 12.78 | E7: ='Monthly Plan'!D8 -> 140 | F7: =SUMPRODUCT((MONTH(Transactions!$A$2:$A$280)=2)*(Transactions!$D$2:$D$280="Gas")*Transactions!$C$2:$C$280) -> 136.71 | G7: =E7-F7 -> 3.29 | H7: ='Monthly Plan'!E8 -> 140 | I7: =SUMPRODUCT((MONTH(Transactions!$A$2:$A$280)=3)*(Transactions!$D$2:$D$280="Gas")*Transactions!$C$2:$C$280) -> 110.27 | J7: =H7-I7 -> 29.73 | K7: ='Monthly Plan'!F8 -> 140 | L7: =SUMPRODUCT((MONTH(Transactions!$A$2:$A$280)=4)*(Transactions!$D$2:$D$280="Gas")*Transactions!$C$2:$C$280) -> 152.17 | M7: =K7-L7 -> -12.17 | N7: ='Monthly Plan'!G8 -> 140 | O7: =SUMPRODUCT((MONTH(Transactions!$A$2:$A$280)=5)*(Transactions!$D$2:$D$280="Gas")*Transactions!$C$2:$C$280) -> 149.69 | P7: =N7-O7 -> -9.69 | Q7: ='Monthly Plan'!H8 -> 140 | R7: =SUMPRODUCT((MONTH(Transactions!$A$2:$A$280)=6)*(Transactions!$D$2:$D$280="Gas")*Transactions!$C$2:$C$280) -> 116.81 | S7: =Q7-R7 -> 23.19 | T7: ='Monthly Plan'!I8 -> 140 | U7: =SUMPRODUCT((MONTH(Transactions!$A$2:$A$280)=7)*(Transactions!$D$2:$D$280="Gas")*Transactions!$C$2:$C$280) -> 175.22 | V7: =T7-U7 -> -35.22 | W7: ='Monthly Plan'!J8 -> 140 | X7: =SUMPRODUCT((MONTH(Transactions!$A$2:$A$280)=8)*(Transactions!$D$2:$D$280="Gas")*Transactions!$C$2:$C$280) -> 104.02 | Y7: =W7-X7 -> 35.98 | Z7: ='Monthly Plan'!K8 -> 140 | AA7: =SUMPRODUCT((MONTH(Transactions!$A$2:$A$280)=9)*(Transactions!$D$2:$D$280="Gas")*Transactions!$C$2:$C$280) -> 102.32 | AB7: =Z7-AA7 -> 37.68 | AC7: ='Monthly Plan'!L8 -> 140 | AD7: =SUMPRODUCT((MONTH(Transactions!$A$2:$A$280)=10)*(Transactions!$D$2:$D$280="Gas")*Transactions!$C$2:$C$280) -> 131.73 | AE7: =AC7-AD7 -> 8.27 | AF7: ='Monthly Plan'!M8 -> 140 | AG7: =SUMPRODUCT((MONTH(Transactions!$A$2:$A$280)=11)*(Transactions!$D$2:$D$280="Gas")*Transactions!$C$2:$C$280) -> 119.31 | AH7: =AF7-AG7 -> 20.69 | AI7: ='Monthly Plan'!N8 -> 140 | AJ7: =SUMPRODUCT((MONTH(Transactions!$A$2:$A$280)=12)*(Transactions!$D$2:$D$280="Gas")*Transactions!$C$2:$C$280) -> 137.55 | AK7: =AI7-AJ7 -> 2.45 | AL7: =B7+E7+H7+K7+N7+Q7+T7+W7+Z7+AC7+AF7+AI7 -> 1680 | AM7: =C7+F7+I7+L7+O7+R7+U7+X7+AA7+AD7+AG7+AJ7 -> 1563.02 | AN7: =AL7-AM7 -> 116.98
A8: Auto Insurance | B8: ='Monthly Plan'!C9 -> 110 | C8: =SUMPRODUCT((MONTH(Transactions!$A$2:$A$280)=1)*(Transactions!$D$2:$D$280="Auto Insurance")*Transactions!$C$2:$C$280) -> 110 | D8: =B8-C8 -> 0 | E8: ='Monthly Plan'!D9 -> 110 | F8: =SUMPRODUCT((MONTH(Transactions!$A$2:$A$280)=2)*(Transactions!$D$2:$D$280="Auto Insurance")*Transactions!$C$2:$C$280) -> 110 | G8: =E8-F8 -> 0 | H8: ='Monthly Plan'!E9 -> 110 | I8: =SUMPRODUCT((MONTH(Transactions!$A$2:$A$280)=3)*(Transactions!$D$2:$D$280="Auto Insurance")*Transactions!$C$2:$C$280) -> 110 | J8: =H8-I8 -> 0 | K8: ='Monthly Plan'!F9 -> 110 | L8: =SUMPRODUCT((MONTH(Transactions!$A$2:$A$280)=4)*(Transactions!$D$2:$D$280="Auto Insurance")*Transactions!$C$2:$C$280) -> 110 | M8: =K8-L8 -> 0 | N8: ='Monthly Plan'!G9 -> 110 | O8: =SUMPRODUCT((MONTH(Transactions!$A$2:$A$280)=5)*(Transactions!$D$2:$D$280="Auto Insurance")*Transactions!$C$2:$C$280) -> 110 | P8: =N8-O8 -> 0 | Q8: ='Monthly Plan'!H9 -> 110 | R8: =SUMPRODUCT((MONTH(Transactions!$A$2:$A$280)=6)*(Transactions!$D$2:$D$280="Auto Insurance")*Transactions!$C$2:$C$280) -> 110 | S8: =Q8-R8 -> 0 | T8: ='Monthly Plan'!I9 -> 110 | U8: =SUMPRODUCT((MONTH(Transactions!$A$2:$A$280)=7)*(Transactions!$D$2:$D$280="Auto Insurance")*Transactions!$C$2:$C$280) -> 110 | V8: =T8-U8 -> 0 | W8: ='Monthly Plan'!J9 -> 110 | X8: =SUMPRODUCT((MONTH(Transactions!$A$2:$A$280)=8)*(Transactions!$D$2:$D$280="Auto Insurance")*Transactions!$C$2:$C$280) -> 110 | Y8: =W8-X8 -> 0 | Z8: ='Monthly Plan'!K9 -> 110 | AA8: =SUMPRODUCT((MONTH(Transactions!$A$2:$A$280)=9)*(Transactions!$D$2:$D$280="Auto Insurance")*Transactions!$C$2:$C$280) -> 110 | AB8: =Z8-AA8 -> 0 | AC8: ='Monthly Plan'!L9 -> 110 | AD8: =SUMPRODUCT((MONTH(Transactions!$A$2:$A$280)=10)*(Transactions!$D$2:$D$280="Auto Insurance")*Transactions!$C$2:$C$280) -> 110 | AE8: =AC8-AD8 -> 0 | AF8: ='Monthly Plan'!M9 -> 110 | AG8: =SUMPRODUCT((MONTH(Transactions!$A$2:$A$280)=11)*(Transactions!$D$2:$D$280="Auto Insurance")*Transactions!$C$2:$C$280) -> 110 | AH8: =AF8-AG8 -> 0 | AI8: ='Monthly Plan'!N9 -> 110 | AJ8: =SUMPRODUCT((MONTH(Transactions!$A$2:$A$280)=12)*(Transactions!$D$2:$D$280="Auto Insurance")*Transactions!$C$2:$C$280) -> 110 | AK8: =AI8-AJ8 -> 0 | AL8: =B8+E8+H8+K8+N8+Q8+T8+W8+Z8+AC8+AF8+AI8 -> 1320 | AM8: =C8+F8+I8+L8+O8+R8+U8+X8+AA8+AD8+AG8+AJ8 -> 1320 | AN8: =AL8-AM8 -> 0
A9: Maintenance | B9: ='Monthly Plan'!C10 -> 50 | C9: =SUMPRODUCT((MONTH(Transactions!$A$2:$A$280)=1)*(Transactions!$D$2:$D$280="Maintenance")*Transactions!$C$2:$C$280) -> 0 | D9: =B9-C9 -> 50 | E9: ='Monthly Plan'!D10 -> 50 | F9: =SUMPRODUCT((MONTH(Transactions!$A$2:$A$280)=2)*(Transactions!$D$2:$D$280="Maintenance")*Transactions!$C$2:$C$280) -> 0 | G9: =E9-F9 -> 50 | H9: ='Monthly Plan'!E10 -> 50 | I9: =SUMPRODUCT((MONTH(Transactions!$A$2:$A$280)=3)*(Transactions!$D$2:$D$280="Maintenance")*Transactions!$C$2:$C$280) -> 0 | J9: =H9-I9 -> 50 | K9: ='Monthly Plan'!F10 -> 50 | L9: =SUMPRODUCT((MONTH(Transactions!$A$2:$A$280)=4)*(Transactions!$D$2:$D$280="Maintenance")*Transactions!$C$2:$C$280) -> 0 | M9: =K9-L9 -> 50 | N9: ='Monthly Plan'!G10 -> 50 | O9: =SUMPRODUCT((MONTH(Transactions!$A$2:$A$280)=5)*(Transactions!$D$2:$D$280="Maintenance")*Transactions!$C$2:$C$280) -> 0 | P9: =N9-O9 -> 50 | Q9: ='Monthly Plan'!H10 -> 50 | R9: =SUMPRODUCT((MONTH(Transactions!$A$2:$A$280)=6)*(Transactions!$D$2:$D$280="Maintenance")*Transactions!$C$2:$C$280) -> 0 | S9: =Q9-R9 -> 50 | T9: ='Monthly Plan'!I10 -> 50 | U9: =SUMPRODUCT((MONTH(Transactions!$A$2:$A$280)=7)*(Transactions!$D$2:$D$280="Maintenance")*Transactions!$C$2:$C$280) -> 45.88 | V9: =T9-U9 -> 4.12 | W9: ='Monthly Plan'!J10 -> 50 | X9: =SUMPRODUCT((MONTH(Transactions!$A$2:$A$280)=8)*(Transactions!$D$2:$D$280="Maintenance")*Transactions!$C$2:$C$280) -> 0 | Y9: =W9-X9 -> 50 | Z9: ='Monthly Plan'!K10 -> 50 | AA9: =SUMPRODUCT((MONTH(Transactions!$A$2:$A$280)=9)*(Transactions!$D$2:$D$280="Maintenance")*Transactions!$C$2:$C$280) -> 0 | AB9: =Z9-AA9 -> 50 | AC9: ='Monthly Plan'!L10 -> 50 | AD9: =SUMPRODUCT((MONTH(Transactions!$A$2:$A$280)=10)*(Transactions!$D$2:$D$280="Maintenance")*Transactions!$C$2:$C$280) -> 0 | AE9: =AC9-AD9 -> 50 | AF9: ='Monthly Plan'!M10 -> 50 | AG9: =SUMPRODUCT((MONTH(Transactions!$A$2:$A$280)=11)*(Transactions!$D$2:$D$280="Maintenance")*Transactions!$C$2:$C$280) -> 0 | AH9: =AF9-AG9 -> 50 | AI9: ='Monthly Plan'!N10 -> 50 | AJ9: =SUMPRODUCT((MONTH(Transactions!$A$2:$A$280)=12)*(Transactions!$D$2:$D$280="Maintenance")*Transactions!$C$2:$C$280) -> 142.27 | AK9: =AI9-AJ9 -> -92.27 | AL9: =B9+E9+H9+K9+N9+Q9+T9+W9+Z9+AC9+AF9+AI9 -> 600 | AM9: =C9+F9+I9+L9+O9+R9+U9+X9+AA9+AD9+AG9+AJ9 -> 188.15 | AN9: =AL9-AM9 -> 411.85
A10: Parking | B10: ='Monthly Plan'!C11 -> 30 | C10: =SUMPRODUCT((MONTH(Transactions!$A$2:$A$280)=1)*(Transactions!$D$2:$D$280="Parking")*Transactions!$C$2:$C$280) -> 11.61 | D10: =B10-C10 -> 18.39 | E10: ='Monthly Plan'!D11 -> 30 | F10: =SUMPRODUCT((MONTH(Transactions!$A$2:$A$280)=2)*(Transactions!$D$2:$D$280="Parking")*Transactions!$C$2:$C$280) -> 12.69 | G10: =E10-F10 -> 17.31 | H10: ='Monthly Plan'!E11 -> 30 | I10: =SUMPRODUCT((MONTH(Transactions!$A$2:$A$280)=3)*(Transactions!$D$2:$D$280="Parking")*Transactions!$C$2:$C$280) -> 7.14 | J10: =H10-I10 -> 22.86 | K10: ='Monthly Plan'!F11 -> 30 | L10: =SUMPRODUCT((MONTH(Transactions!$A$2:$A$280)=4)*(Transactions!$D$2:$D$280="Parking")*Transactions!$C$2:$C$280) -> 10.79 | M10: =K10-L10 -> 19.21 | N10: ='Monthly Plan'!G11 -> 30 | O10: =SUMPRODUCT((MONTH(Transactions!$A$2:$A$280)=5)*(Transactions!$D$2:$D$280="Parking")*Transactions!$C$2:$C$280) -> 7.72 | P10: =N10-O10 -> 22.28 | Q10: ='Monthly Plan'!H11 -> 30 | R10: =SUMPRODUCT((MONTH(Transactions!$A$2:$A$280)=6)*(Transactions!$D$2:$D$280="Parking")*Transactions!$C$2:$C$280) -> 13.59 | S10: =Q10-R10 -> 16.41 | T10: ='Monthly Plan'!I11 -> 30 | U10: =SUMPRODUCT((MONTH(Transactions!$A$2:$A$280)=7)*(Transactions!$D$2:$D$280="Parking")*Transactions!$C$2:$C$280) -> 10.11 | V10: =T10-U10 -> 19.89 | W10: ='Monthly Plan'!J11 -> 30 | X10: =SUMPRODUCT((MONTH(Transactions!$A$2:$A$280)=8)*(Transactions!$D$2:$D$280="Parking")*Transactions!$C$2:$C$280) -> 12.14 | Y10: =W10-X10 -> 17.86 | Z10: ='Monthly Plan'!K11 -> 30 | AA10: =SUMPRODUCT((MONTH(Transactions!$A$2:$A$280)=9)*(Transactions!$D$2:$D$280="Parking")*Transactions!$C$2:$C$280) -> 8.38 | AB10: =Z10-AA10 -> 21.62 | AC10: ='Monthly Plan'!L11 -> 30 | AD10: =SUMPRODUCT((MONTH(Transactions!$A$2:$A$280)=10)*(Transactions!$D$2:$D$280="Parking")*Transactions!$C$2:$C$280) -> 9.35 | AE10: =AC10-AD10 -> 20.65 | AF10: ='Monthly Plan'!M11 -> 30 | AG10: =SUMPRODUCT((MONTH(Transactions!$A$2:$A$280)=11)*(Transactions!$D$2:$D$280="Parking")*Transactions!$C$2:$C$280) -> 12.03 | AH10: =AF10-AG10 -> 17.97 | AI10: ='Monthly Plan'!N11 -> 30 | AJ10: =SUMPRODUCT((MONTH(Transactions!$A$2:$A$280)=12)*(Transactions!$D$2:$D$280="Parking")*Transactions!$C$2:$C$280) -> 8.05 | AK10: =AI10-AJ10 -> 21.95 | AL10: =B10+E10+H10+K10+N10+Q10+T10+W10+Z10+AC10+AF10+AI10 -> 360 | AM10: =C10+F10+I10+L10+O10+R10+U10+X10+AA10+AD10+AG10+AJ10 -> 123.6 | AN10: =AL10-AM10 -> 236.4
A11: Groceries | B11: ='Monthly Plan'!C12 -> 420 | C11: =SUMPRODUCT((MONTH(Transactions!$A$2:$A$280)=1)*(Transactions!$D$2:$D$280="Groceries")*Transactions!$C$2:$C$280) -> 94.09 | D11: =B11-C11 -> 325.91 | E11: ='Monthly Plan'!D12 -> 420 | F11: =SUMPRODUCT((MONTH(Transactions!$A$2:$A$280)=2)*(Transactions!$D$2:$D$280="Groceries")*Transactions!$C$2:$C$280) -> 119.88 | G11: =E11-F11 -> 300.12 | H11: ='Monthly Plan'!E12 -> 420 | I11: =SUMPRODUCT((MONTH(Transactions!$A$2:$A$280)=3)*(Transactions!$D$2:$D$280="Groceries")*Transactions!$C$2:$C$280) -> 356.79 | J11: =H11-I11 -> 63.21 | K11: ='Monthly Plan'!F12 -> 420 | L11: =SUMPRODUCT((MONTH(Transactions!$A$2:$A$280)=4)*(Transactions!$D$2:$D$280="Groceries")*Transactions!$C$2:$C$280) -> 96.65 | M11: =K11-L11 -> 323.35 | N11: ='Monthly Plan'!G12 -> 420 | O11: =SUMPRODUCT((MONTH(Transactions!$A$2:$A$280)=5)*(Transactions!$D$2:$D$280="Groceries")*Transactions!$C$2:$C$280) -> 110.24 | P11: =N11-O11 -> 309.76 | Q11: ='Monthly Plan'!H12 -> 420 | R11: =SUMPRODUCT((MONTH(Transactions!$A$2:$A$280)=6)*(Transactions!$D$2:$D$280="Groceries")*Transactions!$C$2:$C$280) -> 377.28 | S11: =Q11-R11 -> 42.72 | T11: ='Monthly Plan'!I12 -> 420 | U11: =SUMPRODUCT((MONTH(Transactions!$A$2:$A$280)=7)*(Transactions!$D$2:$D$280="Groceries")*Transactions!$C$2:$C$280) -> 340.97 | V11: =T11-U11 -> 79.03 | W11: ='Monthly Plan'!J12 -> 420 | X11: =SUMPRODUCT((MONTH(Transactions!$A$2:$A$280)=8)*(Transactions!$D$2:$D$280="Groceries")*Transactions!$C$2:$C$280) -> 122.06 | Y11: =W11-X11 -> 297.94 | Z11: ='Monthly Plan'!K12 -> 420 | AA11: =SUMPRODUCT((MONTH(Transactions!$A$2:$A$280)=9)*(Transactions!$D$2:$D$280="Groceries")*Transactions!$C$2:$C$280) -> 361.88 | AB11: =Z11-AA11 -> 58.12 | AC11: ='Monthly Plan'!L12 -> 420 | AD11: =SUMPRODUCT((MONTH(Transactions!$A$2:$A$280)=10)*(Transactions!$D$2:$D$280="Groceries")*Transactions!$C$2:$C$280) -> 94.08 | AE11: =AC11-AD11 -> 325.92 | AF11: ='Monthly Plan'!M12 -> 420 | AG11: =SUMPRODUCT((MONTH(Transactions!$A$2:$A$280)=11)*(Transactions!$D$2:$D$280="Groceries")*Transactions!$C$2:$C$280) -> 225.55 | AH11: =AF11-AG11 -> 194.45 | AI11: ='Monthly Plan'!N12 -> 420 | AJ11: =SUMPRODUCT((MONTH(Transactions!$A$2:$A$280)=12)*(Transactions!$D$2:$D$280="Groceries")*Transactions!$C$2:$C$280) -> 206.13 | AK11: =AI11-AJ11 -> 213.87 | AL11: =B11+E11+H11+K11+N11+Q11+T11+W11+Z11+AC11+AF11+AI11 -> 5040 | AM11: =C11+F11+I11+L11+O11+R11+U11+X11+AA11+AD11+AG11+AJ11 -> 2505.6 | AN11: =AL11-AM11 -> 2534.4
A12: Dining Out | B12: ='Monthly Plan'!C13 -> 180 | C12: =SUMPRODUCT((MONTH(Transactions!$A$2:$A$280)=1)*(Transactions!$D$2:$D$280="Dining Out")*Transactions!$C$2:$C$280) -> 37.96 | D12: =B12-C12 -> 142.04 | E12: ='Monthly Plan'!D13 -> 180 | F12: =SUMPRODUCT((MONTH(Transactions!$A$2:$A$280)=2)*(Transactions!$D$2:$D$280="Dining Out")*Transactions!$C$2:$C$280) -> 55.91 | G12: =E12-F12 -> 124.09 | H12: ='Monthly Plan'!E13 -> 180 | I12: =SUMPRODUCT((MONTH(Transactions!$A$2:$A$280)=3)*(Transactions!$D$2:$D$280="Dining Out")*Transactions!$C$2:$C$280) -> 90.8 | J12: =H12-I12 -> 89.2 | K12: ='Monthly Plan'!F13 -> 180 | L12: =SUMPRODUCT((MONTH(Transactions!$A$2:$A$280)=4)*(Transactions!$D$2:$D$280="Dining Out")*Transactions!$C$2:$C$280) -> 105.18 | M12: =K12-L12 -> 74.82 | N12: ='Monthly Plan'!G13 -> 180 | O12: =SUMPRODUCT((MONTH(Transactions!$A$2:$A$280)=5)*(Transactions!$D$2:$D$280="Dining Out")*Transactions!$C$2:$C$280) -> 80.65 | P12: =N12-O12 -> 99.35 | Q12: ='Monthly Plan'!H13 -> 180 | R12: =SUMPRODUCT((MONTH(Transactions!$A$2:$A$280)=6)*(Transactions!$D$2:$D$280="Dining Out")*Transactions!$C$2:$C$280) -> 90.17 | S12: =Q12-R12 -> 89.83 | T12: ='Monthly Plan'!I13 -> 180 | U12: =SUMPRODUCT((MONTH(Transactions!$A$2:$A$280)=7)*(Transactions!$D$2:$D$280="Dining Out")*Transactions!$C$2:$C$280) -> 87.4 | V12: =T12-U12 -> 92.6 | W12: ='Monthly Plan'!J13 -> 180 | X12: =SUMPRODUCT((MONTH(Transactions!$A$2:$A$280)=8)*(Transactions!$D$2:$D$280="Dining Out")*Transactions!$C$2:$C$280) -> 144.54 | Y12: =W12-X12 -> 35.46 | Z12: ='Monthly Plan'!K13 -> 180 | AA12: =SUMPRODUCT((MONTH(Transactions!$A$2:$A$280)=9)*(Transactions!$D$2:$D$280="Dining Out")*Transactions!$C$2:$C$280) -> 17.84 | AB12: =Z12-AA12 -> 162.16 | AC12: ='Monthly Plan'!L13 -> 180 | AD12: =SUMPRODUCT((MONTH(Transactions!$A$2:$A$280)=10)*(Transactions!$D$2:$D$280="Dining Out")*Transactions!$C$2:$C$280) -> 88.14 | AE12: =AC12-AD12 -> 91.86 | AF12: ='Monthly Plan'!M13 -> 180 | AG12: =SUMPRODUCT((MONTH(Transactions!$A$2:$A$280)=11)*(Transactions!$D$2:$D$280="Dining Out")*Transactions!$C$2:$C$280) -> 29.39 | AH12: =AF12-AG12 -> 150.61 | AI12: ='Monthly Plan'!N13 -> 180 | AJ12: =SUMPRODUCT((MONTH(Transactions!$A$2:$A$280)=12)*(Transactions!$D$2:$D$280="Dining Out")*Transactions!$C$2:$C$280) -> 72.25 | AK12: =AI12-AJ12 -> 107.75 | AL12: =B12+E12+H12+K12+N12+Q12+T12+W12+Z12+AC12+AF12+AI12 -> 2160 | AM12: =C12+F12+I12+L12+O12+R12+U12+X12+AA12+AD12+AG12+AJ12 -> 900.23 | AN12: =AL12-AM12 -> 1259.77
A13: Coffee | B13: ='Monthly Plan'!C14 -> 45 | C13: =SUMPRODUCT((MONTH(Transactions!$A$2:$A$280)=1)*(Transactions!$D$2:$D$280="Coffee")*Transactions!$C$2:$C$280) -> 21.52 | D13: =B13-C13 -> 23.48 | E13: ='Monthly Plan'!D14 -> 45 | F13: =SUMPRODUCT((MONTH(Transactions!$A$2:$A$280)=2)*(Transactions!$D$2:$D$280="Coffee")*Transactions!$C$2:$C$280) -> 20.15 | G13: =E13-F13 -> 24.85 | H13: ='Monthly Plan'!E14 -> 45 | I13: =SUMPRODUCT((MONTH(Transactions!$A$2:$A$280)=3)*(Transactions!$D$2:$D$280="Coffee")*Transactions!$C$2:$C$280) -> 12.83 | J13: =H13-I13 -> 32.17 | K13: ='Monthly Plan'!F14 -> 45 | L13: =SUMPRODUCT((MONTH(Transactions!$A$2:$A$280)=4)*(Transactions!$D$2:$D$280="Coffee")*Transactions!$C$2:$C$280) -> 11.41 | M13: =K13-L13 -> 33.59 | N13: ='Monthly Plan'!G14 -> 45 | O13: =SUMPRODUCT((MONTH(Transactions!$A$2:$A$280)=5)*(Transactions!$D$2:$D$280="Coffee")*Transactions!$C$2:$C$280) -> 21.99 | P13: =N13-O13 -> 23.01 | Q13: ='Monthly Plan'!H14 -> 45 | R13: =SUMPRODUCT((MONTH(Transactions!$A$2:$A$280)=6)*(Transactions!$D$2:$D$280="Coffee")*Transactions!$C$2:$C$280) -> 7.15 | S13: =Q13-R13 -> 37.85 | T13: ='Monthly Plan'!I14 -> 45 | U13: =SUMPRODUCT((MONTH(Transactions!$A$2:$A$280)=7)*(Transactions!$D$2:$D$280="Coffee")*Transactions!$C$2:$C$280) -> 16.32 | V13: =T13-U13 -> 28.68 | W13: ='Monthly Plan'!J14 -> 45 | X13: =SUMPRODUCT((MONTH(Transactions!$A$2:$A$280)=8)*(Transactions!$D$2:$D$280="Coffee")*Transactions!$C$2:$C$280) -> 13.87 | Y13: =W13-X13 -> 31.13 | Z13: ='Monthly Plan'!K14 -> 45 | AA13: =SUMPRODUCT((MONTH(Transactions!$A$2:$A$280)=9)*(Transactions!$D$2:$D$280="Coffee")*Transactions!$C$2:$C$280) -> 5.52 | AB13: =Z13-AA13 -> 39.48 | AC13: ='Monthly Plan'!L14 -> 45 | AD13: =SUMPRODUCT((MONTH(Transactions!$A$2:$A$280)=10)*(Transactions!$D$2:$D$280="Coffee")*Transactions!$C$2:$C$280) -> 13.83 | AE13: =AC13-AD13 -> 31.17 | AF13: ='Monthly Plan'!M14 -> 45 | AG13: =SUMPRODUCT((MONTH(Transactions!$A$2:$A$280)=11)*(Transactions!$D$2:$D$280="Coffee")*Transactions!$C$2:$C$280) -> 13.88 | AH13: =AF13-AG13 -> 31.12 | AI13: ='Monthly Plan'!N14 -> 45 | AJ13: =SUMPRODUCT((MONTH(Transactions!$A$2:$A$280)=12)*(Transactions!$D$2:$D$280="Coffee")*Transactions!$C$2:$C$280) -> 5.8 | AK13: =AI13-AJ13 -> 39.2 | AL13: =B13+E13+H13+K13+N13+Q13+T13+W13+Z13+AC13+AF13+AI13 -> 540 | AM13: =C13+F13+I13+L13+O13+R13+U13+X13+AA13+AD13+AG13+AJ13 -> 164.27 | AN13: =AL13-AM13 -> 375.73
A14: Clothing | B14: ='Monthly Plan'!C15 -> 75 | C14: =SUMPRODUCT((MONTH(Transactions!$A$2:$A$280)=1)*(Transactions!$D$2:$D$280="Clothing")*Transactions!$C$2:$C$280) -> 0 | D14: =B14-C14 -> 75 | E14: ='Monthly Plan'!D15 -> 75 | F14: =SUMPRODUCT((MONTH(Transactions!$A$2:$A$280)=2)*(Transactions!$D$2:$D$280="Clothing")*Transactions!$C$2:$C$280) -> 57.39 | G14: =E14-F14 -> 17.61 | H14: ='Monthly Plan'!E15 -> 75 | I14: =SUMPRODUCT((MONTH(Transactions!$A$2:$A$280)=3)*(Transactions!$D$2:$D$280="Clothing")*Transactions!$C$2:$C$280) -> 0 | J14: =H14-I14 -> 75 | K14: ='Monthly Plan'!F15 -> 75 | L14: =SUMPRODUCT((MONTH(Transactions!$A$2:$A$280)=4)*(Transactions!$D$2:$D$280="Clothing")*Transactions!$C$2:$C$280) -> 0 | M14: =K14-L14 -> 75 | N14: ='Monthly Plan'!G15 -> 75 | O14: =SUMPRODUCT((MONTH(Transactions!$A$2:$A$280)=5)*(Transactions!$D$2:$D$280="Clothing")*Transactions!$C$2:$C$280) -> 0 | P14: =N14-O14 -> 75 | Q14: ='Monthly Plan'!H15 -> 75 | R14: =SUMPRODUCT((MONTH(Transactions!$A$2:$A$280)=6)*(Transactions!$D$2:$D$280="Clothing")*Transactions!$C$2:$C$280) -> 0 | S14: =Q14-R14 -> 75 | T14: ='Monthly Plan'!I15 -> 75 | U14: =SUMPRODUCT((MONTH(Transactions!$A$2:$A$280)=7)*(Transactions!$D$2:$D$280="Clothing")*Transactions!$C$2:$C$280) -> 0 | V14: =T14-U14 -> 75 | W14: ='Monthly Plan'!J15 -> 75 | X14: =SUMPRODUCT((MONTH(Transactions!$A$2:$A$280)=8)*(Transactions!$D$2:$D$280="Clothing")*Transactions!$C$2:$C$280) -> 54.66 | Y14: =W14-X14 -> 20.34 | Z14: ='Monthly Plan'!K15 -> 75 | AA14: =SUMPRODUCT((MONTH(Transactions!$A$2:$A$280)=9)*(Transactions!$D$2:$D$280="Clothing")*Transactions!$C$2:$C$280) -> 0 | AB14: =Z14-AA14 -> 75 | AC14: ='Monthly Plan'!L15 -> 75 | AD14: =SUMPRODUCT((MONTH(Transactions!$A$2:$A$280)=10)*(Transactions!$D$2:$D$280="Clothing")*Transactions!$C$2:$C$280) -> 0 | AE14: =AC14-AD14 -> 75 | AF14: ='Monthly Plan'!M15 -> 75 | AG14: =SUMPRODUCT((MONTH(Transactions!$A$2:$A$280)=11)*(Transactions!$D$2:$D$280="Clothing")*Transactions!$C$2:$C$280) -> 0 | AH14: =AF14-AG14 -> 75 | AI14: ='Monthly Plan'!N15 -> 75 | AJ14: =SUMPRODUCT((MONTH(Transactions!$A$2:$A$280)=12)*(Transactions!$D$2:$D$280="Clothing")*Transactions!$C$2:$C$280) -> 0 | AK14: =AI14-AJ14 -> 75 | AL14: =B14+E14+H14+K14+N14+Q14+T14+W14+Z14+AC14+AF14+AI14 -> 900 | AM14: =C14+F14+I14+L14+O14+R14+U14+X14+AA14+AD14+AG14+AJ14 -> 112.05 | AN14: =AL14-AM14 -> 787.95
A15: Haircuts | B15: ='Monthly Plan'!C16 -> 30 | C15: =SUMPRODUCT((MONTH(Transactions!$A$2:$A$280)=1)*(Transactions!$D$2:$D$280="Haircuts")*Transactions!$C$2:$C$280) -> 0 | D15: =B15-C15 -> 30 | E15: ='Monthly Plan'!D16 -> 30 | F15: =SUMPRODUCT((MONTH(Transactions!$A$2:$A$280)=2)*(Transactions!$D$2:$D$280="Haircuts")*Transactions!$C$2:$C$280) -> 0 | G15: =E15-F15 -> 30 | H15: ='Monthly Plan'!E16 -> 30 | I15: =SUMPRODUCT((MONTH(Transactions!$A$2:$A$280)=3)*(Transactions!$D$2:$D$280="Haircuts")*Transactions!$C$2:$C$280) -> 0 | J15: =H15-I15 -> 30 | K15: ='Monthly Plan'!F16 -> 30 | L15: =SUMPRODUCT((MONTH(Transactions!$A$2:$A$280)=4)*(Transactions!$D$2:$D$280="Haircuts")*Transactions!$C$2:$C$280) -> 0 | M15: =K15-L15 -> 30 | N15: ='Monthly Plan'!G16 -> 30 | O15: =SUMPRODUCT((MONTH(Transactions!$A$2:$A$280)=5)*(Transactions!$D$2:$D$280="Haircuts")*Transactions!$C$2:$C$280) -> 0 | P15: =N15-O15 -> 30 | Q15: ='Monthly Plan'!H16 -> 30 | R15: =SUMPRODUCT((MONTH(Transactions!$A$2:$A$280)=6)*(Transactions!$D$2:$D$280="Haircuts")*Transactions!$C$2:$C$280) -> 27.97 | S15: =Q15-R15 -> 2.03 | T15: ='Monthly Plan'!I16 -> 30 | U15: =SUMPRODUCT((MONTH(Transactions!$A$2:$A$280)=7)*(Transactions!$D$2:$D$280="Haircuts")*Transactions!$C$2:$C$280) -> 0 | V15: =T15-U15 -> 30 | W15: ='Monthly Plan'!J16 -> 30 | X15: =SUMPRODUCT((MONTH(Transactions!$A$2:$A$280)=8)*(Transactions!$D$2:$D$280="Haircuts")*Transactions!$C$2:$C$280) -> 0 | Y15: =W15-X15 -> 30 | Z15: ='Monthly Plan'!K16 -> 30 | AA15: =SUMPRODUCT((MONTH(Transactions!$A$2:$A$280)=9)*(Transactions!$D$2:$D$280="Haircuts")*Transactions!$C$2:$C$280) -> 0 | AB15: =Z15-AA15 -> 30 | AC15: ='Monthly Plan'!L16 -> 30 | AD15: =SUMPRODUCT((MONTH(Transactions!$A$2:$A$280)=10)*(Transactions!$D$2:$D$280="Haircuts")*Transactions!$C$2:$C$280) -> 0 | AE15: =AC15-AD15 -> 30 | AF15: ='Monthly Plan'!M16 -> 30 | AG15: =SUMPRODUCT((MONTH(Transactions!$A$2:$A$280)=11)*(Transactions!$D$2:$D$280="Haircuts")*Transactions!$C$2:$C$280) -> 34.86 | AH15: =AF15-AG15 -> -4.86 | AI15: ='Monthly Plan'!N16 -> 30 | AJ15: =SUMPRODUCT((MONTH(Transactions!$A$2:$A$280)=12)*(Transactions!$D$2:$D$280="Haircuts")*Transactions!$C$2:$C$280) -> 0 | AK15: =AI15-AJ15 -> 30 | AL15: =B15+E15+H15+K15+N15+Q15+T15+W15+Z15+AC15+AF15+AI15 -> 360 | AM15: =C15+F15+I15+L15+O15+R15+U15+X15+AA15+AD15+AG15+AJ15 -> 62.83 | AN15: =AL15-AM15 -> 297.17
A16: Subscriptions | B16: ='Monthly Plan'!C17 -> 55 | C16: =SUMPRODUCT((MONTH(Transactions!$A$2:$A$280)=1)*(Transactions!$D$2:$D$280="Subscriptions")*Transactions!$C$2:$C$280) -> 0 | D16: =B16-C16 -> 55 | E16: ='Monthly Plan'!D17 -> 55 | F16: =SUMPRODUCT((MONTH(Transactions!$A$2:$A$280)=2)*(Transactions!$D$2:$D$280="Subscriptions")*Transactions!$C$2:$C$280) -> 0 | G16: =E16-F16 -> 55 | H16: ='Monthly Plan'!E17 -> 55 | I16: =SUMPRODUCT((MONTH(Transactions!$A$2:$A$280)=3)*(Transactions!$D$2:$D$280="Subscriptions")*Transactions!$C$2:$C$280) -> 0 | J16: =H16-I16 -> 55 | K16: ='Monthly Plan'!F17 -> 55 | L16: =SUMPRODUCT((MONTH(Transactions!$A$2:$A$280)=4)*(Transactions!$D$2:$D$280="Subscriptions")*Transactions!$C$2:$C$280) -> 0 | M16: =K16-L16 -> 55 | N16: ='Monthly Plan'!G17 -> 55 | O16: =SUMPRODUCT((MONTH(Transactions!$A$2:$A$280)=5)*(Transactions!$D$2:$D$280="Subscriptions")*Transactions!$C$2:$C$280) -> 0 | P16: =N16-O16 -> 55 | Q16: ='Monthly Plan'!H17 -> 55 | R16: =SUMPRODUCT((MONTH(Transactions!$A$2:$A$280)=6)*(Transactions!$D$2:$D$280="Subscriptions")*Transactions!$C$2:$C$280) -> 0 | S16: =Q16-R16 -> 55 | T16: ='Monthly Plan'!I17 -> 55 | U16: =SUMPRODUCT((MONTH(Transactions!$A$2:$A$280)=7)*(Transactions!$D$2:$D$280="Subscriptions")*Transactions!$C$2:$C$280) -> 0 | V16: =T16-U16 -> 55 | W16: ='Monthly Plan'!J17 -> 55 | X16: =SUMPRODUCT((MONTH(Transactions!$A$2:$A$280)=8)*(Transactions!$D$2:$D$280="Subscriptions")*Transactions!$C$2:$C$280) -> 0 | Y16: =W16-X16 -> 55 | Z16: ='Monthly Plan'!K17 -> 55 | AA16: =SUMPRODUCT((MONTH(Transactions!$A$2:$A$280)=9)*(Transactions!$D$2:$D$280="Subscriptions")*Transactions!$C$2:$C$280) -> 0 | AB16: =Z16-AA16 -> 55 | AC16: ='Monthly Plan'!L17 -> 55 | AD16: =SUMPRODUCT((MONTH(Transactions!$A$2:$A$280)=10)*(Transactions!$D$2:$D$280="Subscriptions")*Transactions!$C$2:$C$280) -> 0 | AE16: =AC16-AD16 -> 55 | AF16: ='Monthly Plan'!M17 -> 55 | AG16: =SUMPRODUCT((MONTH(Transactions!$A$2:$A$280)=11)*(Transactions!$D$2:$D$280="Subscriptions")*Transactions!$C$2:$C$280) -> 0 | AH16: =AF16-AG16 -> 55 | AI16: ='Monthly Plan'!N17 -> 55 | AJ16: =SUMPRODUCT((MONTH(Transactions!$A$2:$A$280)=12)*(Transactions!$D$2:$D$280="Subscriptions")*Transactions!$C$2:$C$280) -> 0 | AK16: =AI16-AJ16 -> 55 | AL16: =B16+E16+H16+K16+N16+Q16+T16+W16+Z16+AC16+AF16+AI16 -> 660 | AM16: =C16+F16+I16+L16+O16+R16+U16+X16+AA16+AD16+AG16+AJ16 -> 0 | AN16: =AL16-AM16 -> 660
A17: Entertainment | B17: ='Monthly Plan'!C18 -> 80 | C17: =SUMPRODUCT((MONTH(Transactions!$A$2:$A$280)=1)*(Transactions!$D$2:$D$280="Entertainment")*Transactions!$C$2:$C$280) -> 69.22 | D17: =B17-C17 -> 10.78 | E17: ='Monthly Plan'!D18 -> 80 | F17: =SUMPRODUCT((MONTH(Transactions!$A$2:$A$280)=2)*(Transactions!$D$2:$D$280="Entertainment")*Transactions!$C$2:$C$280) -> 0 | G17: =E17-F17 -> 80 | H17: ='Monthly Plan'!E18 -> 80 | I17: =SUMPRODUCT((MONTH(Transactions!$A$2:$A$280)=3)*(Transactions!$D$2:$D$280="Entertainment")*Transactions!$C$2:$C$280) -> 0 | J17: =H17-I17 -> 80 | K17: ='Monthly Plan'!F18 -> 80 | L17: =SUMPRODUCT((MONTH(Transactions!$A$2:$A$280)=4)*(Transactions!$D$2:$D$280="Entertainment")*Transactions!$C$2:$C$280) -> 0 | M17: =K17-L17 -> 80 | N17: ='Monthly Plan'!G18 -> 80 | O17: =SUMPRODUCT((MONTH(Transactions!$A$2:$A$280)=5)*(Transactions!$D$2:$D$280="Entertainment")*Transactions!$C$2:$C$280) -> 31.32 | P17: =N17-O17 -> 48.68 | Q17: ='Monthly Plan'!H18 -> 80 | R17: =SUMPRODUCT((MONTH(Transactions!$A$2:$A$280)=6)*(Transactions!$D$2:$D$280="Entertainment")*Transactions!$C$2:$C$280) -> 0 | S17: =Q17-R17 -> 80 | T17: ='Monthly Plan'!I18 -> 80 | U17: =SUMPRODUCT((MONTH(Transactions!$A$2:$A$280)=7)*(Transactions!$D$2:$D$280="Entertainment")*Transactions!$C$2:$C$280) -> 0 | V17: =T17-U17 -> 80 | W17: ='Monthly Plan'!J18 -> 80 | X17: =SUMPRODUCT((MONTH(Transactions!$A$2:$A$280)=8)*(Transactions!$D$2:$D$280="Entertainment")*Transactions!$C$2:$C$280) -> 0 | Y17: =W17-X17 -> 80 | Z17: ='Monthly Plan'!K18 -> 80 | AA17: =SUMPRODUCT((MONTH(Transactions!$A$2:$A$280)=9)*(Transactions!$D$2:$D$280="Entertainment")*Transactions!$C$2:$C$280) -> 0 | AB17: =Z17-AA17 -> 80 | AC17: ='Monthly Plan'!L18 -> 80 | AD17: =SUMPRODUCT((MONTH(Transactions!$A$2:$A$280)=10)*(Transactions!$D$2:$D$280="Entertainment")*Transactions!$C$2:$C$280) -> 0 | AE17: =AC17-AD17 -> 80 | AF17: ='Monthly Plan'!M18 -> 80 | AG17: =SUMPRODUCT((MONTH(Transactions!$A$2:$A$280)=11)*(Transactions!$D$2:$D$280="Entertainment")*Transactions!$C$2:$C$280) -> 0 | AH17: =AF17-AG17 -> 80 | AI17: ='Monthly Plan'!N18 -> 80 | AJ17: =SUMPRODUCT((MONTH(Transactions!$A$2:$A$280)=12)*(Transactions!$D$2:$D$280="Entertainment")*Transactions!$C$2:$C$280) -> 0 | AK17: =AI17-AJ17 -> 80 | AL17: =B17+E17+H17+K17+N17+Q17+T17+W17+Z17+AC17+AF17+AI17 -> 960 | AM17: =C17+F17+I17+L17+O17+R17+U17+X17+AA17+AD17+AG17+AJ17 -> 100.54 | AN17: =AL17-AM17 -> 859.46
A18: Gifts | B18: ='Monthly Plan'!C19 -> 40 | C18: =SUMPRODUCT((MONTH(Transactions!$A$2:$A$280)=1)*(Transactions!$D$2:$D$280="Gifts")*Transactions!$C$2:$C$280) -> 0 | D18: =B18-C18 -> 40 | E18: ='Monthly Plan'!D19 -> 40 | F18: =SUMPRODUCT((MONTH(Transactions!$A$2:$A$280)=2)*(Transactions!$D$2:$D$280="Gifts")*Transactions!$C$2:$C$280) -> 0 | G18: =E18-F18 -> 40 | H18: ='Monthly Plan'!E19 -> 40 | I18: =SUMPRODUCT((MONTH(Transactions!$A$2:$A$280)=3)*(Transactions!$D$2:$D$280="Gifts")*Transactions!$C$2:$C$280) -> 25.82 | J18: =H18-I18 -> 14.18 | K18: ='Monthly Plan'!F19 -> 40 | L18: =SUMPRODUCT((MONTH(Transactions!$A$2:$A$280)=4)*(Transactions!$D$2:$D$280="Gifts")*Transactions!$C$2:$C$280) -> 29.45 | M18: =K18-L18 -> 10.55 | N18: ='Monthly Plan'!G19 -> 40 | O18: =SUMPRODUCT((MONTH(Transactions!$A$2:$A$280)=5)*(Transactions!$D$2:$D$280="Gifts")*Transactions!$C$2:$C$280) -> 0 | P18: =N18-O18 -> 40 | Q18: ='Monthly Plan'!H19 -> 40 | R18: =SUMPRODUCT((MONTH(Transactions!$A$2:$A$280)=6)*(Transactions!$D$2:$D$280="Gifts")*Transactions!$C$2:$C$280) -> 0 | S18: =Q18-R18 -> 40 | T18: ='Monthly Plan'!I19 -> 40 | U18: =SUMPRODUCT((MONTH(Transactions!$A$2:$A$280)=7)*(Transactions!$D$2:$D$280="Gifts")*Transactions!$C$2:$C$280) -> 0 | V18: =T18-U18 -> 40 | W18: ='Monthly Plan'!J19 -> 40 | X18: =SUMPRODUCT((MONTH(Transactions!$A$2:$A$280)=8)*(Transactions!$D$2:$D$280="Gifts")*Transactions!$C$2:$C$280) -> 0 | Y18: =W18-X18 -> 40 | Z18: ='Monthly Plan'!K19 -> 40 | AA18: =SUMPRODUCT((MONTH(Transactions!$A$2:$A$280)=9)*(Transactions!$D$2:$D$280="Gifts")*Transactions!$C$2:$C$280) -> 52.37 | AB18: =Z18-AA18 -> -12.37 | AC18: ='Monthly Plan'!L19 -> 40 | AD18: =SUMPRODUCT((MONTH(Transactions!$A$2:$A$280)=10)*(Transactions!$D$2:$D$280="Gifts")*Transactions!$C$2:$C$280) -> 69.54 | AE18: =AC18-AD18 -> -29.54 | AF18: ='Monthly Plan'!M19 -> 40 | AG18: =SUMPRODUCT((MONTH(Transactions!$A$2:$A$280)=11)*(Transactions!$D$2:$D$280="Gifts")*Transactions!$C$2:$C$280) -> 0 | AH18: =AF18-AG18 -> 40 | AI18: ='Monthly Plan'!N19 -> 40 | AJ18: =SUMPRODUCT((MONTH(Transactions!$A$2:$A$280)=12)*(Transactions!$D$2:$D$280="Gifts")*Transactions!$C$2:$C$280) -> 0 | AK18: =AI18-AJ18 -> 40 | AL18: =B18+E18+H18+K18+N18+Q18+T18+W18+Z18+AC18+AF18+AI18 -> 480 | AM18: =C18+F18+I18+L18+O18+R18+U18+X18+AA18+AD18+AG18+AJ18 -> 177.18 | AN18: =AL18-AM18 -> 302.82
A19: Health Insurance | B19: ='Monthly Plan'!C20 -> 210 | C19: =SUMPRODUCT((MONTH(Transactions!$A$2:$A$280)=1)*(Transactions!$D$2:$D$280="Health Insurance")*Transactions!$C$2:$C$280) -> 210 | D19: =B19-C19 -> 0 | E19: ='Monthly Plan'!D20 -> 210 | F19: =SUMPRODUCT((MONTH(Transactions!$A$2:$A$280)=2)*(Transactions!$D$2:$D$280="Health Insurance")*Transactions!$C$2:$C$280) -> 210 | G19: =E19-F19 -> 0 | H19: ='Monthly Plan'!E20 -> 210 | I19: =SUMPRODUCT((MONTH(Transactions!$A$2:$A$280)=3)*(Transactions!$D$2:$D$280="Health Insurance")*Transactions!$C$2:$C$280) -> 210 | J19: =H19-I19 -> 0 | K19: ='Monthly Plan'!F20 -> 210 | L19: =SUMPRODUCT((MONTH(Transactions!$A$2:$A$280)=4)*(Transactions!$D$2:$D$280="Health Insurance")*Transactions!$C$2:$C$280) -> 210 | M19: =K19-L19 -> 0 | N19: ='Monthly Plan'!G20 -> 210 | O19: =SUMPRODUCT((MONTH(Transactions!$A$2:$A$280)=5)*(Transactions!$D$2:$D$280="Health Insurance")*Transactions!$C$2:$C$280) -> 210 | P19: =N19-O19 -> 0 | Q19: ='Monthly Plan'!H20 -> 210 | R19: =SUMPRODUCT((MONTH(Transactions!$A$2:$A$280)=6)*(Transactions!$D$2:$D$280="Health Insurance")*Transactions!$C$2:$C$280) -> 210 | S19: =Q19-R19 -> 0 | T19: ='Monthly Plan'!I20 -> 210 | U19: =SUMPRODUCT((MONTH(Transactions!$A$2:$A$280)=7)*(Transactions!$D$2:$D$280="Health Insurance")*Transactions!$C$2:$C$280) -> 210 | V19: =T19-U19 -> 0 | W19: ='Monthly Plan'!J20 -> 210 | X19: =SUMPRODUCT((MONTH(Transactions!$A$2:$A$280)=8)*(Transactions!$D$2:$D$280="Health Insurance")*Transactions!$C$2:$C$280) -> 210 | Y19: =W19-X19 -> 0 | Z19: ='Monthly Plan'!K20 -> 210 | AA19: =SUMPRODUCT((MONTH(Transactions!$A$2:$A$280)=9)*(Transactions!$D$2:$D$280="Health Insurance")*Transactions!$C$2:$C$280) -> 210 | AB19: =Z19-AA19 -> 0 | AC19: ='Monthly Plan'!L20 -> 210 | AD19: =SUMPRODUCT((MONTH(Transactions!$A$2:$A$280)=10)*(Transactions!$D$2:$D$280="Health Insurance")*Transactions!$C$2:$C$280) -> 210 | AE19: =AC19-AD19 -> 0 | AF19: ='Monthly Plan'!M20 -> 210 | AG19: =SUMPRODUCT((MONTH(Transactions!$A$2:$A$280)=11)*(Transactions!$D$2:$D$280="Health Insurance")*Transactions!$C$2:$C$280) -> 210 | AH19: =AF19-AG19 -> 0 | AI19: ='Monthly Plan'!N20 -> 210 | AJ19: =SUMPRODUCT((MONTH(Transactions!$A$2:$A$280)=12)*(Transactions!$D$2:$D$280="Health Insurance")*Transactions!$C$2:$C$280) -> 210 | AK19: =AI19-AJ19 -> 0 | AL19: =B19+E19+H19+K19+N19+Q19+T19+W19+Z19+AC19+AF19+AI19 -> 2520 | AM19: =C19+F19+I19+L19+O19+R19+U19+X19+AA19+AD19+AG19+AJ19 -> 2520 | AN19: =AL19-AM19 -> 0
A20: Gym | B20: ='Monthly Plan'!C21 -> 45 | C20: =SUMPRODUCT((MONTH(Transactions!$A$2:$A$280)=1)*(Transactions!$D$2:$D$280="Gym")*Transactions!$C$2:$C$280) -> 45 | D20: =B20-C20 -> 0 | E20: ='Monthly Plan'!D21 -> 45 | F20: =SUMPRODUCT((MONTH(Transactions!$A$2:$A$280)=2)*(Transactions!$D$2:$D$280="Gym")*Transactions!$C$2:$C$280) -> 45 | G20: =E20-F20 -> 0 | H20: ='Monthly Plan'!E21 -> 45 | I20: =SUMPRODUCT((MONTH(Transactions!$A$2:$A$280)=3)*(Transactions!$D$2:$D$280="Gym")*Transactions!$C$2:$C$280) -> 45 | J20: =H20-I20 -> 0 | K20: ='Monthly Plan'!F21 -> 45 | L20: =SUMPRODUCT((MONTH(Transactions!$A$2:$A$280)=4)*(Transactions!$D$2:$D$280="Gym")*Transactions!$C$2:$C$280) -> 45 | M20: =K20-L20 -> 0 | N20: ='Monthly Plan'!G21 -> 45 | O20: =SUMPRODUCT((MONTH(Transactions!$A$2:$A$280)=5)*(Transactions!$D$2:$D$280="Gym")*Transactions!$C$2:$C$280) -> 45 | P20: =N20-O20 -> 0 | Q20: ='Monthly Plan'!H21 -> 45 | R20: =SUMPRODUCT((MONTH(Transactions!$A$2:$A$280)=6)*(Transactions!$D$2:$D$280="Gym")*Transactions!$C$2:$C$280) -> 45 | S20: =Q20-R20 -> 0 | T20: ='Monthly Plan'!I21 -> 45 | U20: =SUMPRODUCT((MONTH(Transactions!$A$2:$A$280)=7)*(Transactions!$D$2:$D$280="Gym")*Transactions!$C$2:$C$280) -> 45 | V20: =T20-U20 -> 0 | W20: ='Monthly Plan'!J21 -> 45 | X20: =SUMPRODUCT((MONTH(Transactions!$A$2:$A$280)=8)*(Transactions!$D$2:$D$280="Gym")*Transactions!$C$2:$C$280) -> 45 | Y20: =W20-X20 -> 0 | Z20: ='Monthly Plan'!K21 -> 45 | AA20: =SUMPRODUCT((MONTH(Transactions!$A$2:$A$280)=9)*(Transactions!$D$2:$D$280="Gym")*Transactions!$C$2:$C$280) -> 45 | AB20: =Z20-AA20 -> 0 | AC20: ='Monthly Plan'!L21 -> 45 | AD20: =SUMPRODUCT((MONTH(Transactions!$A$2:$A$280)=10)*(Transactions!$D$2:$D$280="Gym")*Transactions!$C$2:$C$280) -> 45 | AE20: =AC20-AD20 -> 0 | AF20: ='Monthly Plan'!M21 -> 45 | AG20: =SUMPRODUCT((MONTH(Transactions!$A$2:$A$280)=11)*(Transactions!$D$2:$D$280="Gym")*Transactions!$C$2:$C$280) -> 45 | AH20: =AF20-AG20 -> 0 | AI20: ='Monthly Plan'!N21 -> 45 | AJ20: =SUMPRODUCT((MONTH(Transactions!$A$2:$A$280)=12)*(Transactions!$D$2:$D$280="Gym")*Transactions!$C$2:$C$280) -> 45 | AK20: =AI20-AJ20 -> 0 | AL20: =B20+E20+H20+K20+N20+Q20+T20+W20+Z20+AC20+AF20+AI20 -> 540 | AM20: =C20+F20+I20+L20+O20+R20+U20+X20+AA20+AD20+AG20+AJ20 -> 540 | AN20: =AL20-AM20 -> 0
A21: Prescriptions | B21: ='Monthly Plan'!C22 -> 20 | C21: =SUMPRODUCT((MONTH(Transactions!$A$2:$A$280)=1)*(Transactions!$D$2:$D$280="Prescriptions")*Transactions!$C$2:$C$280) -> 27.33 | D21: =B21-C21 -> -7.33 | E21: ='Monthly Plan'!D22 -> 20 | F21: =SUMPRODUCT((MONTH(Transactions!$A$2:$A$280)=2)*(Transactions!$D$2:$D$280="Prescriptions")*Transactions!$C$2:$C$280) -> 18.7 | G21: =E21-F21 -> 1.3 | H21: ='Monthly Plan'!E22 -> 20 | I21: =SUMPRODUCT((MONTH(Transactions!$A$2:$A$280)=3)*(Transactions!$D$2:$D$280="Prescriptions")*Transactions!$C$2:$C$280) -> 14.86 | J21: =H21-I21 -> 5.14 | K21: ='Monthly Plan'!F22 -> 20 | L21: =SUMPRODUCT((MONTH(Transactions!$A$2:$A$280)=4)*(Transactions!$D$2:$D$280="Prescriptions")*Transactions!$C$2:$C$280) -> 11.14 | M21: =K21-L21 -> 8.86 | N21: ='Monthly Plan'!G22 -> 20 | O21: =SUMPRODUCT((MONTH(Transactions!$A$2:$A$280)=5)*(Transactions!$D$2:$D$280="Prescriptions")*Transactions!$C$2:$C$280) -> 14.07 | P21: =N21-O21 -> 5.93 | Q21: ='Monthly Plan'!H22 -> 20 | R21: =SUMPRODUCT((MONTH(Transactions!$A$2:$A$280)=6)*(Transactions!$D$2:$D$280="Prescriptions")*Transactions!$C$2:$C$280) -> 16.99 | S21: =Q21-R21 -> 3.01 | T21: ='Monthly Plan'!I22 -> 20 | U21: =SUMPRODUCT((MONTH(Transactions!$A$2:$A$280)=7)*(Transactions!$D$2:$D$280="Prescriptions")*Transactions!$C$2:$C$280) -> 15.68 | V21: =T21-U21 -> 4.32 | W21: ='Monthly Plan'!J22 -> 20 | X21: =SUMPRODUCT((MONTH(Transactions!$A$2:$A$280)=8)*(Transactions!$D$2:$D$280="Prescriptions")*Transactions!$C$2:$C$280) -> 16.39 | Y21: =W21-X21 -> 3.61 | Z21: ='Monthly Plan'!K22 -> 20 | AA21: =SUMPRODUCT((MONTH(Transactions!$A$2:$A$280)=9)*(Transactions!$D$2:$D$280="Prescriptions")*Transactions!$C$2:$C$280) -> 15.05 | AB21: =Z21-AA21 -> 4.95 | AC21: ='Monthly Plan'!L22 -> 20 | AD21: =SUMPRODUCT((MONTH(Transactions!$A$2:$A$280)=10)*(Transactions!$D$2:$D$280="Prescriptions")*Transactions!$C$2:$C$280) -> 22.32 | AE21: =AC21-AD21 -> -2.32 | AF21: ='Monthly Plan'!M22 -> 20 | AG21: =SUMPRODUCT((MONTH(Transactions!$A$2:$A$280)=11)*(Transactions!$D$2:$D$280="Prescriptions")*Transactions!$C$2:$C$280) -> 14.61 | AH21: =AF21-AG21 -> 5.39 | AI21: ='Monthly Plan'!N22 -> 20 | AJ21: =SUMPRODUCT((MONTH(Transactions!$A$2:$A$280)=12)*(Transactions!$D$2:$D$280="Prescriptions")*Transactions!$C$2:$C$280) -> 28.95 | AK21: =AI21-AJ21 -> -8.95 | AL21: =B21+E21+H21+K21+N21+Q21+T21+W21+Z21+AC21+AF21+AI21 -> 240 | AM21: =C21+F21+I21+L21+O21+R21+U21+X21+AA21+AD21+AG21+AJ21 -> 216.09 | AN21: =AL21-AM21 -> 23.91
